Workbook

Sheet Sheet1
A1: 字结构： 一个16位字包含：
A2: 14位 数据/操作码
A3: 1位 符号位
A4: 1位 奇偶校验位
A5: 数据格式： 使用补码表示负数，大部分计算采用分数制（数值范围约在-1到+1之间），以简化三角函数和导航方程的计算
A6: 2. 指令集关键特点
A7: AGC的指令分为两大类，由指令字的高3位决定
A8: A. 常见操作码
A9: 以下是AGC汇编语言中的关键指令助记符及其功能：
A10: TC： 转移控制
A12: 最重要的指令之一。执行无条件跳转或子程序调用。
A13: TC K 会跳转到地址K，并将返回地址保存在一个特殊的寄存器Q中。因此，子程序返回通过 TC Q 实现。
... A53: CYR, SR, CYL 等： 用于移位的临时寄存器。

Sheet Sheet2
A1: AGC指令编码格式
A2: 一个15位指令字（不含奇偶位）的位格式：
A3: text
A4: 14 13 12 11 10 09 08 07 06 05 04 03 02 01 00
A5: ┌───┬───────────────────┬───────────────────┐
A6: │OP │ 寄存器/特殊码 │ 内存地址/数据 │
A7: └───┴───────────────────┴───────────────────┘
A8: 3位 3位 9位

Sheet 80C51
A1: RAM
A2: 0 | B2: =DEC2HEX(A2) -> 0 | C2: R0 | D2: 32 | E2: =DEC2HEX(D2) -> 20 | G2: 64 | H2: =DEC2HEX(G2) -> 40 | J2: 96 | K2: =DEC2HEX(J2) -> 60 | M2: 128 | N2: =DEC2HEX(M2) -> 80 | O2: P0 | P2: 160 | Q2: =DEC2HEX(P2) -> A0 | R2: P2 | S2: 192 | T2: =DEC2HEX(S2) -> C0 | V2: 224 | W2: =DEC2HEX(V2) -> E0 | X2: ACC
A3: 1 | B3: =DEC2HEX(A3) -> 1 | C3: R1 | D3: 33 | E3: =DEC2HEX(D3) -> 21 | G3: 65 | H3: =DEC2HEX(G3) -> 41 | J3: 97 | K3: =DEC2HEX(J3) -> 61 | M3: 129 | N3: =DEC2HEX(M3) -> 81 | O3: SP=07H | P3: 161 | Q3: =DEC2HEX(P3) -> A1 | S3: 193 | T3: =DEC2HEX(S3) -> C1 | V3: 225 | W3: =DEC2HEX(V3) -> E1
A4: 2 | B4: =DEC2HEX(A4) -> 2 | C4: R2 | D4: 34 | E4: =DEC2HEX(D4) -> 22 | G4: 66 | H4: =DEC2HEX(G4) -> 42 | J4: 98 | K4: =DEC2HEX(J4) -> 62 | M4: 130 | N4: =DEC2HEX(M4) -> 82 | O4: DPL | P4: 162 | Q4: =DEC2HEX(P4) -> A2 | S4: 194 | T4: =DEC2HEX(S4) -> C2 | V4: 226 | W4: =DEC2HEX(V4) -> E2
A5: 3 | B5: =DEC2HEX(A5) -> 3 | C5: R3 | D5: 35 | E5: =DEC2HEX(D5) -> 23 | G5: 67 | H5: =DEC2HEX(G5) -> 43 | J5: 99 | K5: =DEC2HEX(J5) -> 63 | M5: 131 | N5: =DEC2HEX(M5) -> 83 | O5: DPH | P5: 163 | Q5: =DEC2HEX(P5) -> A3 | S5: 195 | T5: =DEC2HEX(S5) -> C3 | V5: 227 | W5: =DEC2HEX(V5) -> E3
A6: 4 | B6: =DEC2HEX(A6) -> 4 | C6: R4 | D6: 36 | E6: =DEC2HEX(D6) -> 24 | G6: 68 | H6: =DEC2HEX(G6) -> 44 | J6: 100 | K6: =DEC2HEX(J6) -> 64 | M6: 132 | N6: =DEC2HEX(M6) -> 84 | P6: 164 | Q6: =DEC2HEX(P6) -> A4 | S6: 196 | T6: =DEC2HEX(S6) -> C4 | V6: 228 | W6: =DEC2HEX(V6) -> E4
A7: 5 | B7: =DEC2HEX(A7) -> 5 | C7: R5 | D7: 37 | E7: =DEC2HEX(D7) -> 25 | G7: 69 | H7: =DEC2HEX(G7) -> 45 | J7: 101 | K7: =DEC2HEX(J7) -> 65 | M7: 133 | N7: =DEC2HEX(M7) -> 85 | P7: 165 | Q7: =DEC2HEX(P7) -> A5 | S7: 197 | T7: =DEC2HEX(S7) -> C5 | V7: 229 | W7: =DEC2HEX(V7) -> E5
A8: 6 | B8: =DEC2HEX(A8) -> 6 | C8: R6 | D8: 38 | E8: =DEC2HEX(D8) -> 26 | G8: 70 | H8: =DEC2HEX(G8) -> 46 | J8: 102 | K8: =DEC2HEX(J8) -> 66 | M8: 134 | N8: =DEC2HEX(M8) -> 86 | P8: 166 | Q8: =DEC2HEX(P8) -> A6 | S8: 198 | T8: =DEC2HEX(S8) -> C6 | V8: 230 | W8: =DEC2HEX(V8) -> E6
A9: 7 | B9: =DEC2HEX(A9) -> 7 | C9: R7 | D9: 39 | E9: =DEC2HEX(D9) -> 27 | G9: 71 | H9: =DEC2HEX(G9) -> 47 | J9: 103 | K9: =DEC2HEX(J9) -> 67 | M9: 135 | N9: =DEC2HEX(M9) -> 87 | O9: PCON | P9: 167 | Q9: =DEC2HEX(P9) -> A7 | S9: 199 | T9: =DEC2HEX(S9) -> C7 | V9: 231 | W9: =DEC2HEX(V9) -> E7
A10: 8 | B10: =DEC2HEX(A10) -> 8 | C10: R0 | D10: 40 | E10: =DEC2HEX(D10) -> 28 | G10: 72 | H10: =DEC2HEX(G10) -> 48 | J10: 104 | K10: =DEC2HEX(J10) -> 68 | M10: 136 | N10: =DEC2HEX(M10) -> 88 | O10: TCON | P10: 168 | Q10: =DEC2HEX(P10) -> A8 | R10: IE | S10: 200 | T10: =DEC2HEX(S10) -> C8 | V10: 232 | W10: =DEC2HEX(V10) -> E8
A11: 9 | B11: =DEC2HEX(A11) -> 9 | C11: R1 | D11: 41 | E11: =DEC2HEX(D11) -> 29 | G11: 73 | H11: =DEC2HEX(G11) -> 49 | J11: 105 | K11: =DEC2HEX(J11) -> 69 | M11: 137 | N11: =DEC2HEX(M11) -> 89 | O11: TMOD | P11: 169 | Q11: =DEC2HEX(P11) -> A9 | S11: 201 | T11: =DEC2HEX(S11) -> C9 | V11: 233 | W11: =DEC2HEX(V11) -> E9
A12: 10 | B12: =DEC2HEX(A12) -> A | C12: R2 | D12: 42 | E12: =DEC2HEX(D12) -> 2A | G12: 74 | H12: =DEC2HEX(G12) -> 4A | J12: 106 | K12: =DEC2HEX(J12) -> 6A | M12: 138 | N12: =DEC2HEX(M12) -> 8A | O12: TL0 | P12: 170 | Q12: =DEC2HEX(P12) -> AA | S12: 202 | T12: =DEC2HEX(S12) -> CA | V12: 234 | W12: =DEC2HEX(V12) -> EA
A13: 11 | B13: =DEC2HEX(A13) -> B | C13: R3 | D13: 43 | E13: =DEC2HEX(D13) -> 2B | G13: 75 | H13: =DEC2HEX(G13) -> 4B | J13: 107 | K13: =DEC2HEX(J13) -> 6B | M13: 139 | N13: =DEC2HEX(M13) -> 8B | O13: TL1 | P13: 171 | Q13: =DEC2HEX(P13) -> AB | S13: 203 | T13: =DEC2HEX(S13) -> CB | V13: 235 | W13: =DEC2HEX(V13) -> EB
A14: 12 | B14: =DEC2HEX(A14) -> C | C14: R4 | D14: 44 | E14: =DEC2HEX(D14) -> 2C | G14: 76 | H14: =DEC2HEX(G14) -> 4C | J14: 108 | K14: =DEC2HEX(J14) -> 6C | M14: 140 | N14: =DEC2HEX(M14) -> 8C | O14: TH0 | P14: 172 | Q14: =DEC2HEX(P14) -> AC | S14: 204 | T14: =DEC2HEX(S14) -> CC | V14: 236 | W14: =DEC2HEX(V14) -> EC
A15: 13 | B15: =DEC2HEX(A15) -> D | C15: R5 | D15: 45 | E15: =DEC2HEX(D15) -> 2D | G15: 77 | H15: =DEC2HEX(G15) -> 4D | J15: 109 | K15: =DEC2HEX(J15) -> 6D | M15: 141 | N15: =DEC2HEX(M15) -> 8D | O15: TH1 | P15: 173 | Q15: =DEC2HEX(P15) -> AD | S15: 205 | T15: =DEC2HEX(S15) -> CD | V15: 237 | W15: =DEC2HEX(V15) -> ED
A16: 14 | B16: =DEC2HEX(A16) -> E | C16: R6 | D16: 46 | E16: =DEC2HEX(D16) -> 2E | G16: 78 | H16: =DEC2HEX(G16) -> 4E | J16: 110 | K16: =DEC2HEX(J16) -> 6E | M16: 142 | N16: =DEC2HEX(M16) -> 8E | P16: 174 | Q16: =DEC2HEX(P16) -> AE | S16: 206 | T16: =DEC2HEX(S16) -> CE | V16: 238 | W16: =DEC2HEX(V16) -> EE
A17: 15 | B17: =DEC2HEX(A17) -> F | C17: R7 | D17: 47 | E17: =DEC2HEX(D17) -> 2F | G17: 79 | H17: =DEC2HEX(G17) -> 4F | J17: 111 | K17: =DEC2HEX(J17) -> 6F | M17: 143 | N17: =DEC2HEX(M17) -> 8F | P17: 175 | Q17: =DEC2HEX(P17) -> AF | S17: 207 | T17: =DEC2HEX(S17) -> CF | V17: 239 | W17: =DEC2HEX(V17) -> EF
A18: 16 | B18: =DEC2HEX(A18) -> 10 | C18: R0 | D18: 48 | E18: =DEC2HEX(D18) -> 30 | G18: 80 | H18: =DEC2HEX(G18) -> 50 | J18: 112 | K18: =DEC2HEX(J18) -> 70 | M18: 144 | N18: =DEC2HEX(M18) -> 90 | O18: P1 | P18: 176 | Q18: =DEC2HEX(P18) -> B0 | R18: P3 | S18: 208 | T18: =DEC2HEX(S18) -> D0 | U18: PSW | V18: 240 | W18: =DEC2HEX(V18) -> F0 | X18: B寄存器
A19: 17 | B19: =DEC2HEX(A19) -> 11 | C19: R1 | D19: 49 | E19: =DEC2HEX(D19) -> 31 | G19: 81 | H19: =DEC2HEX(G19) -> 51 | J19: 113 | K19: =DEC2HEX(J19) -> 71 | M19: 145 | N19: =DEC2HEX(M19) -> 91 | P19: 177 | Q19: =DEC2HEX(P19) -> B1 | S19: 209 | T19: =DEC2HEX(S19) -> D1 | V19: 241 | W19: =DEC2HEX(V19) -> F1
A20: 18 | B20: =DEC2HEX(A20) -> 12 | C20: R2 | D20: 50 | E20: =DEC2HEX(D20) -> 32 | G20: 82 | H20: =DEC2HEX(G20) -> 52 | J20: 114 | K20: =DEC2HEX(J20) -> 72 | M20: 146 | N20: =DEC2HEX(M20) -> 92 | P20: 178 | Q20: =DEC2HEX(P20) -> B2 | S20: 210 | T20: =DEC2HEX(S20) -> D2 | V20: 242 | W20: =DEC2HEX(V20) -> F2
A21: 19 | B21: =DEC2HEX(A21) -> 13 | C21: R3 | D21: 51 | E21: =DEC2HEX(D21) -> 33 | G21: 83 | H21: =DEC2HEX(G21) -> 53 | J21: 115 | K21: =DEC2HEX(J21) -> 73 | M21: 147 | N21: =DEC2HEX(M21) -> 93 | P21: 179 | Q21: =DEC2HEX(P21) -> B3 | S21: 211 | T21: =DEC2HEX(S21) -> D3 | V21: 243 | W21: =DEC2HEX(V21) -> F3
A22: 20 | B22: =DEC2HEX(A22) -> 14 | C22: R4 | D22: 52 | E22: =DEC2HEX(D22) -> 34 | G22: 84 | H22: =DEC2HEX(G22) -> 54 | J22: 116 | K22: =DEC2HEX(J22) -> 74 | M22: 148 | N22: =DEC2HEX(M22) -> 94 | P22: 180 | Q22: =DEC2HEX(P22) -> B4 | S22: 212 | T22: =DEC2HEX(S22) -> D4 | V22: 244 | W22: =DEC2HEX(V22) -> F4
A23: 21 | B23: =DEC2HEX(A23) -> 15 | C23: R5 | D23: 53 | E23: =DEC2HEX(D23) -> 35 | G23: 85 | H23: =DEC2HEX(G23) -> 55 | J23: 117 | K23: =DEC2HEX(J23) -> 75 | M23: 149 | N23: =DEC2HEX(M23) -> 95 | P23: 181 | Q23: =DEC2HEX(P23) -> B5 | S23: 213 | T23: =DEC2HEX(S23) -> D5 | V23: 245 | W23: =DEC2HEX(V23) -> F5
A24: 22 | B24: =DEC2HEX(A24) -> 16 | C24: R6 | D24: 54 | E24: =DEC2HEX(D24) -> 36 | G24: 86 | H24: =DEC2HEX(G24) -> 56 | J24: 118 | K24: =DEC2HEX(J24) -> 76 | M24: 150 | N24: =DEC2HEX(M24) -> 96 | P24: 182 | Q24: =DEC2HEX(P24) -> B6 | S24: 214 | T24: =DEC2HEX(S24) -> D6 | V24: 246 | W24: =DEC2HEX(V24) -> F6
A25: 23 | B25: =DEC2HEX(A25) -> 17 | C25: R7 | D25: 55 | E25: =DEC2HEX(D25) -> 37 | G25: 87 | H25: =DEC2HEX(G25) -> 57 | J25: 119 | K25: =DEC2HEX(J25) -> 77 | M25: 151 | N25: =DEC2HEX(M25) -> 97 | P25: 183 | Q25: =DEC2HEX(P25) -> B7 | S25: 215 | T25: =DEC2HEX(S25) -> D7 | V25: 247 | W25: =DEC2HEX(V25) -> F7
A26: 24 | B26: =DEC2HEX(A26) -> 18 | C26: R0 | D26: 56 | E26: =DEC2HEX(D26) -> 38 | G26: 88 | H26: =DEC2HEX(G26) -> 58 | J26: 120 | K26: =DEC2HEX(J26) -> 78 | M26: 152 | N26: =DEC2HEX(M26) -> 98 | O26: SCON | P26: 184 | Q26: =DEC2HEX(P26) -> B8 | R26: IP | S26: 216 | T26: =DEC2HEX(S26) -> D8 | V26: 248 | W26: =DEC2HEX(V26) -> F8
A27: 25 | B27: =DEC2HEX(A27) -> 19 | C27: R1 | D27: 57 | E27: =DEC2HEX(D27) -> 39 | G27: 89 | H27: =DEC2HEX(G27) -> 59 | J27: 121 | K27: =DEC2HEX(J27) -> 79 | M27: 153 | N27: =DEC2HEX(M27) -> 99 | O27: SBUF | P27: 185 | Q27: =DEC2HEX(P27) -> B9 | S27: 217 | T27: =DEC2HEX(S27) -> D9 | V27: 249 | W27: =DEC2HEX(V27) -> F9 | AA27: =POWER(2,16) -> 65536
A28: 26 | B28: =DEC2HEX(A28) -> 1A | C28: R2 | D28: 58 | E28: =DEC2HEX(D28) -> 3A | G28: 90 | H28: =DEC2HEX(G28) -> 5A | J28: 122 | K28: =DEC2HEX(J28) -> 7A | M28: 154 | N28: =DEC2HEX(M28) -> 9A | P28: 186 | Q28: =DEC2HEX(P28) -> BA | S28: 218 | T28: =DEC2HEX(S28) -> DA | V28: 250 | W28: =DEC2HEX(V28) -> FA
A29: 27 | B29: =DEC2HEX(A29) -> 1B | C29: R3 | D29: 59 | E29: =DEC2HEX(D29) -> 3B | G29: 91 | H29: =DEC2HEX(G29) -> 5B | J29: 123 | K29: =DEC2HEX(J29) -> 7B | M29: 155 | N29: =DEC2HEX(M29) -> 9B | P29: 187 | Q29: =DEC2HEX(P29) -> BB | S29: 219 | T29: =DEC2HEX(S29) -> DB | V29: 251 | W29: =DEC2HEX(V29) -> FB
A30: 28 | B30: =DEC2HEX(A30) -> 1C | C30: R4 | D30: 60 | E30: =DEC2HEX(D30) -> 3C | G30: 92 | H30: =DEC2HEX(G30) -> 5C | J30: 124 | K30: =DEC2HEX(J30) -> 7C | M30: 156 | N30: =DEC2HEX(M30) -> 9C | P30: 188 | Q30: =DEC2HEX(P30) -> BC | S30: 220 | T30: =DEC2HEX(S30) -> DC | V30: 252 | W30: =DEC2HEX(V30) -> FC
A31: 29 | B31: =DEC2HEX(A31) -> 1D | C31: R5 | D31: 61 | E31: =DEC2HEX(D31) -> 3D | G31: 93 | H31: =DEC2HEX(G31) -> 5D | J31: 125 | K31: =DEC2HEX(J31) -> 7D | M31: 157 | N31: =DEC2HEX(M31) -> 9D | P31: 189 | Q31: =DEC2HEX(P31) -> BD | S31: 221 | T31: =DEC2HEX(S31) -> DD | V31: 253 | W31: =DEC2HEX(V31) -> FD
A32: 30 | B32: =DEC2HEX(A32) -> 1E | C32: R6 | D32: 62 | E32: =DEC2HEX(D32) -> 3E | G32: 94 | H32: =DEC2HEX(G32) -> 5E | J32: 126 | K32: =DEC2HEX(J32) -> 7E | M32: 158 | N32: =DEC2HEX(M32) -> 9E | P32: 190 | Q32: =DEC2HEX(P32) -> BE | S32: 222 | T32: =DEC2HEX(S32) -> DE | V32: 254 | W32: =DEC2HEX(V32) -> FE
A33: 31 | B33: =DEC2HEX(A33) -> 1F | C33: R7 | D33: 63 | E33: =DEC2HEX(D33) -> 3F | G33: 95 | H33: =DEC2HEX(G33) -> 5F | J33: 127 | K33: =DEC2HEX(J33) -> 7F | M33: 159 | N33: =DEC2HEX(M33) -> 9F | P33: 191 | Q33: =DEC2HEX(P33) -> BF | S33: 223 | T33: =DEC2HEX(S33) -> DF | V33: 255 | W33: =DEC2HEX(V33) -> FF
A35: ROM地址空间 (程序存储器)
A36: ┌─────────────┐
A37: │ 0000H │ ← 复位向量 (必须放LJMP跳转指令)
A38: ├─────────────┤
A39: │ 0003H │ ← INT0中断入口 (仅8字节空间)
A40: ├─────────────┤
A41: │ 000BH │ ← T0中断入口 (仅8字节空间)
...

Sheet STC90C52汇编指令
A1: 一、数据传送指令 (28条) | J1: 七、标志位速查表
B2: 机器码 | C2: 汇编指令 | D2: 说明 | E2: 字节 | F2: 周期 | G2: 标志位 | J2: 标志位 | K2: 名称 | L2: 位置 | M2: 说明
A3: 1.1 累加器相关 | B3: E8~EF | C3: MOV A, Rn | D3: Rn→A (n=0~7) | E3: 1 | F3: 1 | G3: ×××× | H3: 8 | J3: CY | K3: 进位标志 | L3: PSW.7 | M3: 加减法进位/借位
B4: E5 dd | C4: MOV A, direct | D4: (direct)→A | E4: 2 | F4: 1 | G4: ×××× | H4: 1 | J4: AC | K4: 辅助进位 | L4: PSW.6 | M4: BCD码调整用
B5: E6~E7 | C5: MOV A, @Ri | D5: (Ri)→A (i=0,1) | E5: 1 | F5: 1 | G5: ×××× | H5: 2 | J5: F0 | K5: 用户标志0 | L5: PSW.5 | M5: 用户自定义
B6: 74 xx | C6: MOV A, #data | D6: #data→A | E6: 2 | F6: 1 | G6: ×××× | H6: 1 | J6: RS1 | K6: 寄存器区选择1 | L6: PSW.4 | M6: 00=区0, 01=区1
B7: F8~FF | C7: MOV Rn, A | D7: A→Rn | E7: 1 | F7: 1 | G7: ×××× | H7: 8 | J7: RS0 | K7: 寄存器区选择0 | L7: PSW.3 | M7: 10=区2, 11=区3
B8: A8~AF dd | C8: MOV Rn, direct | D8: (direct)→Rn | E8: 2 | F8: 2 | G8: ×××× | H8: 8 | J8: OV | K8: 溢出标志 | L8: PSW.2 | M8: 有符号溢出
B9: 78~7F xx | C9: MOV Rn, #data | D9: #data→Rn | E9: 2 | F9: 1 | G9: ×××× | H9: 8 | J9: P | K9: 奇偶标志 | L9: PSW.0 | M9: A中1的个数为奇则置1
A10: 1.2 直接地址传送 | B10: F5 dd | C10: MOV direct, A | D10: A→direct | E10: 2 | F10: 1 | H10: 1
B11: 88~8F dd | C11: MOV direct, Rn | D11: Rn→direct | E11: 2 | F11: 2 | H11: 8
B12: 85 dd dd | C12: MOV direct1, direct2 | D12: (direct2)→direct1 | E12: 3 | F12: 2 | H12: 1
B13: 86~87 dd | C13: MOV direct, @Ri | D13: (Ri)→direct | E13: 2 | F13: 2 | H13: 2
B14: 75 dd xx | C14: MOV direct, #data | D14: #data→direct | E14: 3 | F14: 2 | H14: 1
B15: F6~F7 | C15: MOV @Ri, A | D15: A→(Ri) | E15: 1 | F15: 1 | H15: 2
B16: A6~A7 dd | C16: MOV @Ri, direct | D16: (direct)→(Ri) | E16: 2 | F16: 2 | H16: 2
B17: 76~77 xx | C17: MOV @Ri, #data | D17: #data→(Ri) | E17: 2 | F17: 1 | H17: 2
A18: 1.4 16位数据传送 | B18: 90 xx xx | C18: MOV DPTR, #data16 | D18: #data16→DPTR | E18: 3 | F18: 2 | G18: ×××× | H18: 1
A19: 1.5 查表指令 | B19: 83 | C19: MOVC A, @A+PC | D19: (A+PC)→A | E19: 1 | F19: 2 | H19: 1
B20: 93 | C20: MOVC A, @A+DPTR | D20: (A+DPTR)→A | E20: 1 | F20: 2 | H20: 1
A21: 1.6 外部RAM传送 | B21: E2~E3 | C21: MOVX A, @Ri | D21: (Ri)→A (外部) | E21: 1 | F21: 2 | H21: 2
B22: F2~F3 | C22: MOVX @Ri, A | D22: A→(Ri) (外部) | E22: 1 | F22: 2 | H22: 2
B23: E0 | C23: MOVX A, @DPTR | D23: (DPTR)→A (外部) | E23: 1 | F23: 2 | H23: 1
B24: F0 | C24: MOVX @DPTR, A | D24: A→(DPTR) (外部) | E24: 1 | F24: 2 | H24: 1
A25: 1.7 堆栈操作 | B25: C0 dd | C25: PUSH direct | D25: SP←SP+1, (SP)←(direct) | E25: 2 | F25: 2 | H25: 1
B26: D0 dd | C26: POP direct | D26: (direct)←(SP), SP←SP-1 | E26: 2 | F26: 2 | H26: 1
A27: 1.8 交换指令 | B27: C6~C7 | C27: XCH A, @Ri | D27: A↔(Ri) | E27: 1 | F27: 1 | G27: ×××× | H27: 2
B28: C8~CF | C28: XCH A, Rn | D28: A↔Rn | E28: 1 | F28: 1 | G28: ×××× | H28: 8
B29: C5 dd | C29: XCH A, direct | D29: A↔(direct) | E29: 2 | F29: 1 | G29: ×××× | H29: 1
B30: D6~D7 | C30: XCHD A, @Ri | D30: A[3:0]↔(Ri)[3:0] | E30: 1 | F30: 1 | G30: ×××× | H30: 2
A31: 二、算术运算指令 (24条)
B32: 机器码 | C32: 汇编指令 | D32: 说明 | E32: 字节 | F32: 周期 | G32: 标志位影响
A33: 2.1 加法 | B33: 28~2F | C33: ADD A, Rn | D33: A+Rn→A | E33: 1 | F33: 1 | G33: √√√√ | H33: 8
B34: 25 dd | C34: ADD A, direct | D34: A+(direct)→A | E34: 2 | F34: 1 | G34: √√√√ | H34: 1
B35: 26~27 | C35: ADD A, @Ri | D35: A+(Ri)→A | E35: 1 | F35: 1 | G35: √√√√ | H35: 2
B36: 24 xx | C36: ADD A, #data | D36: A+#data→A | E36: 2 | F36: 1 | G36: √√√√ | H36: 1
B37: 38~3F | C37: ADDC A, Rn | D37: A+Rn+CY→A | E37: 1 | F37: 1 | G37: √√√√ | H37: 8
B38: 35 dd | C38: ADDC A, direct | D38: A+(direct)+CY→A | E38: 2 | F38: 1 | G38: √√√√ | H38: 1
B39: 36~37 | C39: ADDC A, @Ri | D39: A+(Ri)+CY→A | E39: 1 | F39: 1 | G39: √√√√ | H39: 2
B40: 34 xx | C40: ADDC A, #data | D40: A+#data+CY→A | E40: 2 | F40: 1 | G40: √√√√ | H40: 1
...

Sheet STC90C52寄存器
A1: 地址范围 | B1: 类型 | C1: 说明
A2: 80H~FFH | B2: SFR空间 | C2: 特殊功能寄存器（可直接寻址）
A3: 00H~7FH | B3: 内部RAM | C3: 低128字节（含工作寄存器组）
A4: 80H~FFH | B4: 内部RAM | C4: 高128字节（间接寻址）
A5: 0000H~FFFFH | B5: 程序存储器 | C5: 8KB/12KB/16KB等（型号相关）
A7: 地址 | B7: 寄存器名 | C7: 复位值 | D7: 位定义（D7→D0） | L7: 功能说明
A8: 80H | B8: P0 | C8: FFH | D8: P0.7 | E8: P0.6 | F8: P0.5 | G8: P0.4 | H8: P0.3 | I8: P0.2 | J8: P0.1 | K8: P0.0 | L8: 端口0，开漏输出
A9: 81H | B9: SP | C9: 07H | D9: - | E9: - | F9: - | G9: - | H9: - | I9: - | J9: - | K9: - | L9: 堆栈指针（默认07H）
A10: 82H | B10: DPL | C10: 00H | D10: DPL[7:0] | L10: 数据指针低8位
A11: 83H | B11: DPH | C11: 00H | D11: DPH[7:0] | L11: 数据指针高8位
A12: 87H | B12: PCON | C12: 00H | D12: SMOD | E12: - | F12: - | G12: POF | H12: GF1 | I12: GF0 | J12: PD | K12: IDL | L12: 电源控制
A13: 88H | B13: TCON | C13: 00H | D13: TF1 | E13: TR1 | F13: TF0 | G13: TR0 | H13: IE1 | I13: IT1 | J13: IE0 | K13: IT0 | L13: 定时器控制
A14: 89H | B14: TMOD | C14: 00H | D14: GATE | E14: C/T | F14: M1 | G14: M0 | H14: GATE | I14: C/T | J14: M1 | K14: M0 | L14: 定时器模式
A15: 8AH | B15: TL0 | C15: 00H | D15: TL0[7:0] | L15: 定时器0低字节
A16: 8BH | B16: TL1 | C16: 00H | D16: TL1[7:0] | L16: 定时器1低字节
A17: 8CH | B17: TH0 | C17: 00H | D17: TH0[7:0] | L17: 定时器0高字节
A18: 8DH | B18: TH1 | C18: 00H | D18: TH1[7:0] | L18: 定时器1高字节
A19: 90H | B19: P1 | C19: FFH | D19: P1.7 | E19: P1.6 | F19: P1.5 | G19: P1.4 | H19: P1.3 | I19: P1.2 | J19: P1.1 | K19: P1.0 | L19: 端口1（准双向）
A20: 98H | B20: SCON | C20: 00H | D20: SM0 | E20: SM1 | F20: SM2 | G20: REN | H20: TB8 | I20: RB8 | J20: TI | K20: RI | L20: 串口控制
A21: 99H | B21: SBUF | C21: 不定 | D21: SBUF[7:0] | L21: 串口数据缓冲
A22: A0H | B22: P2 | C22: FFH | D22: P2.7 | E22: P2.6 | F22: P2.5 | G22: P2.4 | H22: P2.3 | I22: P2.2 | J22: P2.1 | K22: P2.0 | L22: 端口2（准双向）
A23: A8H | B23: IE | C23: 00H | D23: EA | E23: - | F23: ET2 | G23: ES | H23: ET1 | I23: EX1 | J23: ET0 | K23: EX0 | L23: 中断使能
A24: B0H | B24: P3 | C24: FFH | D24: P3.7 | E24: P3.6 | F24: P3.5 | G24: P3.4 | H24: P3.3 | I24: P3.2 | J24: P3.1 | K24: P3.0 | L24: 端口3（复用功能）
A25: B8H | B25: IP | C25: 00H | D25: - | E25: - | F25: PT2 | G25: PS | H25: PT1 | I25: PX1 | J25: PT0 | K25: PX0 | L25: 中断优先级
A26: D0H | B26: PSW | C26: 00H | D26: CY | E26: AC | F26: F0 | G26: RS1 | H26: RS0 | I26: OV | J26: - | K26: P | L26: 程序状态字
A27: E0H | B27: ACC | C27: 00H | D27: ACC[7:0] | L27: 累加器（隐含）
A28: F0H | B28: B | C28: 00H | D28: B[7:0] | L28: B寄存器
A31: TC90C52新增了多个SFR，地址在80H~FFH之间，必须用直接寻址方式访问：
A32: 地址 | B32: 寄存器名 | C32: 复位值 | D32: 主要功能
A33: 8EH | B33: AUXR | C33: 00H | D33: 辅助寄存器：
D34: • DISALE（ALE控制）
D35: • DISRTC（看门狗）
A36: 8FH | B36: AUXR1 | C36: 00H | D36: 辅助寄存器1：
D37: • DPS（DPTR选择）
A38: A2H | B38: AUXR2 | C38: 00H | D38: 辅助寄存器2
A39: A9H | B39: SADDR | C39: 00H | D39: 从机地址寄存器
A40: B7H | B40: IPH | C40: 00H | D40: 中断优先级高
A41: C8H | B41: WDT_CONTR | C41: 00H | D41: 看门狗控制
A42: D1H | B42: P4 | C42: FFH | D42: 端口4（扩展IO）
A43: D8H | B43: T2CON | C43: 00H | D43: 定时器2控制
...

Sheet 汇编状态表
A1: direct 表示直接寻址（00H-FFH），#data 表示立即数（00H-FFH），#data16 表示16位立即数（0000H-FFFFH） rel 表示相对地址（-128~127），addr11 表示11位地址（0000H-07FFH），addr16 表示16位地址（0000H-FFFFH）
E2: =COLUMN()-3 -> 2 | F2: =COLUMN()-3 -> 3 | G2: =COLUMN()-3 -> 4 | H2: =COLUMN()-3 -> 5 | I2: =COLUMN()-3 -> 6 | J2: =COLUMN()-3 -> 7 | K2: =COLUMN()-3 -> 8 | L2: =COLUMN()-3 -> 9 | ... AB2: =COLUMN()-3 -> 25
A3: 参数个数 | C3: 命令 | E3: A | F3: R0 | G3: R1 | H3: R2 | I3: R3 | J3: R4 | K3: R5 | L3: R6 | M3: R7 | N3: #data | O3: direct | P3: @R0 | Q3: @R1 | R3: DPTR | S3: #data16 | T3: @A+PC | U3: @A+DPTR | V3: @DPTR | W3: addr16 | X3: rel | Y3: bit | Z3: C | AA3: AB | AB3: /bit
A4: 0 | B4: =ROW()-4 -> 0 | C4: NOP | D4: =DEC2HEX(B4) -> 0 | E4: =_xlfn.IFNA(VLOOKUP($C4&","&E3,$C$69:$D$112,2,FALSE),"-1") -> -1 | F4: =_xlfn.IFNA(VLOOKUP($C4&","&F3,$C$69:$D$112,2,FALSE),"-1") -> -1 | G4: =_xlfn.IFNA(VLOOKUP($C4&","&G3,$C$69:$D$112,2,FALSE),"-1") -> -1 | H4: =_xlfn.IFNA(VLOOKUP($C4&","&H3,$C$69:$D$112,2,FALSE),"-1") -> -1 | I4: =_xlfn.IFNA(VLOOKUP($C4&","&I3,$C$69:$D$112,2,FALSE),"-1") -> -1 | J4: =_xlfn.IFNA(VLOOKUP($C4&","&J3,$C$69:$D$112,2,FALSE),"-1") -> -1 | K4: =_xlfn.IFNA(VLOOKUP($C4&","&K3,$C$69:$D$112,2,FALSE),"-1") -> -1 | L4: =_xlfn.IFNA(VLOOKUP($C4&","&L3,$C$69:$D$112,2,FALSE),"-1") -> -1 | ... AB4: =_xlfn.IFNA(VLOOKUP($C4&","&AB3,$C$69:$D$112,2,FALSE),"-1") -> -1 | AC4: 0
A5: 0 | B5: =ROW()-4 -> 1 | C5: RET | D5: =DEC2HEX(B5) -> 1 | E5: =_xlfn.IFNA(VLOOKUP($C5&","&E3,$C$69:$D$112,2,FALSE),"-1") -> -1 | F5: =_xlfn.IFNA(VLOOKUP($C5&","&F3,$C$69:$D$112,2,FALSE),"-1") -> -1 | G5: =_xlfn.IFNA(VLOOKUP($C5&","&G3,$C$69:$D$112,2,FALSE),"-1") -> -1 | H5: =_xlfn.IFNA(VLOOKUP($C5&","&H3,$C$69:$D$112,2,FALSE),"-1") -> -1 | I5: =_xlfn.IFNA(VLOOKUP($C5&","&I3,$C$69:$D$112,2,FALSE),"-1") -> -1 | J5: =_xlfn.IFNA(VLOOKUP($C5&","&J3,$C$69:$D$112,2,FALSE),"-1") -> -1 | K5: =_xlfn.IFNA(VLOOKUP($C5&","&K3,$C$69:$D$112,2,FALSE),"-1") -> -1 | L5: =_xlfn.IFNA(VLOOKUP($C5&","&L3,$C$69:$D$112,2,FALSE),"-1") -> -1 | ... AB5: =_xlfn.IFNA(VLOOKUP($C5&","&AB3,$C$69:$D$112,2,FALSE),"-1") -> -1 | AC5: 22
A6: 0 | B6: =ROW()-4 -> 2 | C6: RETI | D6: =DEC2HEX(B6) -> 2 | E6: =_xlfn.IFNA(VLOOKUP($C6&","&E3,$C$69:$D$112,2,FALSE),"-1") -> -1 | F6: =_xlfn.IFNA(VLOOKUP($C6&","&F3,$C$69:$D$112,2,FALSE),"-1") -> -1 | G6: =_xlfn.IFNA(VLOOKUP($C6&","&G3,$C$69:$D$112,2,FALSE),"-1") -> -1 | H6: =_xlfn.IFNA(VLOOKUP($C6&","&H3,$C$69:$D$112,2,FALSE),"-1") -> -1 | I6: =_xlfn.IFNA(VLOOKUP($C6&","&I3,$C$69:$D$112,2,FALSE),"-1") -> -1 | J6: =_xlfn.IFNA(VLOOKUP($C6&","&J3,$C$69:$D$112,2,FALSE),"-1") -> -1 | K6: =_xlfn.IFNA(VLOOKUP($C6&","&K3,$C$69:$D$112,2,FALSE),"-1") -> -1 | L6: =_xlfn.IFNA(VLOOKUP($C6&","&L3,$C$69:$D$112,2,FALSE),"-1") -> -1 | ... AB6: =_xlfn.IFNA(VLOOKUP($C6&","&AB3,$C$69:$D$112,2,FALSE),"-1") -> -1 | AC6: 32
A7: 2 | B7: =ROW()-4 -> 3 | C7: ADD | D7: =DEC2HEX(B7) -> 3 | E7: =_xlfn.IFNA(VLOOKUP($C7&","&E3,$C$34:$D$112,2,FALSE),"-1") -> 35 | F7: =_xlfn.IFNA(VLOOKUP($C7&","&F3,$C$34:$D$112,2,FALSE),"-1") -> -1 | G7: =_xlfn.IFNA(VLOOKUP($C7&","&G3,$C$34:$D$112,2,FALSE),"-1") -> -1 | H7: =_xlfn.IFNA(VLOOKUP($C7&","&H3,$C$34:$D$112,2,FALSE),"-1") -> -1 | I7: =_xlfn.IFNA(VLOOKUP($C7&","&I3,$C$34:$D$112,2,FALSE),"-1") -> -1 | J7: =_xlfn.IFNA(VLOOKUP($C7&","&J3,$C$34:$D$112,2,FALSE),"-1") -> -1 | K7: =_xlfn.IFNA(VLOOKUP($C7&","&K3,$C$34:$D$112,2,FALSE),"-1") -> -1 | L7: =_xlfn.IFNA(VLOOKUP($C7&","&L3,$C$34:$D$112,2,FALSE),"-1") -> -1 | ... AB7: =_xlfn.IFNA(VLOOKUP($C7&","&AB3,$C$34:$D$112,2,FALSE),"-1") -> -1
A8: 2 | B8: =ROW()-4 -> 4 | C8: ADDC | D8: =DEC2HEX(B8) -> 4 | E8: =_xlfn.IFNA(VLOOKUP($C8&","&E3,$C$34:$D$112,2,FALSE),"-1") -> 36 | F8: =_xlfn.IFNA(VLOOKUP($C8&","&F3,$C$34:$D$112,2,FALSE),"-1") -> -1 | G8: =_xlfn.IFNA(VLOOKUP($C8&","&G3,$C$34:$D$112,2,FALSE),"-1") -> -1 | H8: =_xlfn.IFNA(VLOOKUP($C8&","&H3,$C$34:$D$112,2,FALSE),"-1") -> -1 | I8: =_xlfn.IFNA(VLOOKUP($C8&","&I3,$C$34:$D$112,2,FALSE),"-1") -> -1 | J8: =_xlfn.IFNA(VLOOKUP($C8&","&J3,$C$34:$D$112,2,FALSE),"-1") -> -1 | K8: =_xlfn.IFNA(VLOOKUP($C8&","&K3,$C$34:$D$112,2,FALSE),"-1") -> -1 | L8: =_xlfn.IFNA(VLOOKUP($C8&","&L3,$C$34:$D$112,2,FALSE),"-1") -> -1 | ... AB8: =_xlfn.IFNA(VLOOKUP($C8&","&AB3,$C$34:$D$112,2,FALSE),"-1") -> -1
A9: 2 | B9: =ROW()-4 -> 5 | C9: ANL | D9: =DEC2HEX(B9) -> 5 | E9: =_xlfn.IFNA(VLOOKUP($C9&","&E3,$C$34:$D$112,2,FALSE),"-1") -> 37 | F9: =_xlfn.IFNA(VLOOKUP($C9&","&F3,$C$34:$D$112,2,FALSE),"-1") -> -1 | G9: =_xlfn.IFNA(VLOOKUP($C9&","&G3,$C$34:$D$112,2,FALSE),"-1") -> -1 | H9: =_xlfn.IFNA(VLOOKUP($C9&","&H3,$C$34:$D$112,2,FALSE),"-1") -> -1 | I9: =_xlfn.IFNA(VLOOKUP($C9&","&I3,$C$34:$D$112,2,FALSE),"-1") -> -1 | J9: =_xlfn.IFNA(VLOOKUP($C9&","&J3,$C$34:$D$112,2,FALSE),"-1") -> -1 | K9: =_xlfn.IFNA(VLOOKUP($C9&","&K3,$C$34:$D$112,2,FALSE),"-1") -> -1 | L9: =_xlfn.IFNA(VLOOKUP($C9&","&L3,$C$34:$D$112,2,FALSE),"-1") -> -1 | ... AB9: =_xlfn.IFNA(VLOOKUP($C9&","&AB3,$C$34:$D$112,2,FALSE),"-1") -> -1
A10: 2 | B10: =ROW()-4 -> 6 | C10: DJNZ | D10: =DEC2HEX(B10) -> 6 | E10: =_xlfn.IFNA(VLOOKUP($C10&","&E3,$C$34:$D$112,2,FALSE),"-1") -> -1 | F10: =_xlfn.IFNA(VLOOKUP($C10&","&F3,$C$34:$D$112,2,FALSE),"-1") -> 3A | G10: =_xlfn.IFNA(VLOOKUP($C10&","&G3,$C$34:$D$112,2,FALSE),"-1") -> 3B | H10: =_xlfn.IFNA(VLOOKUP($C10&","&H3,$C$34:$D$112,2,FALSE),"-1") -> 3C | I10: =_xlfn.IFNA(VLOOKUP($C10&","&I3,$C$34:$D$112,2,FALSE),"-1") -> 3D | J10: =_xlfn.IFNA(VLOOKUP($C10&","&J3,$C$34:$D$112,2,FALSE),"-1") -> 3E | K10: =_xlfn.IFNA(VLOOKUP($C10&","&K3,$C$34:$D$112,2,FALSE),"-1") -> 3F | L10: =_xlfn.IFNA(VLOOKUP($C10&","&L3,$C$34:$D$112,2,FALSE),"-1") -> 40 | ... AB10: =_xlfn.IFNA(VLOOKUP($C10&","&AB3,$C$34:$D$112,2,FALSE),"-1") -> -1
A11: 2 | B11: =ROW()-4 -> 7 | C11: JB | D11: =DEC2HEX(B11) -> 7 | E11: =_xlfn.IFNA(VLOOKUP($C11&","&E3,$C$34:$D$112,2,FALSE),"-1") -> -1 | F11: =_xlfn.IFNA(VLOOKUP($C11&","&F3,$C$34:$D$112,2,FALSE),"-1") -> -1 | G11: =_xlfn.IFNA(VLOOKUP($C11&","&G3,$C$34:$D$112,2,FALSE),"-1") -> -1 | H11: =_xlfn.IFNA(VLOOKUP($C11&","&H3,$C$34:$D$112,2,FALSE),"-1") -> -1 | I11: =_xlfn.IFNA(VLOOKUP($C11&","&I3,$C$34:$D$112,2,FALSE),"-1") -> -1 | J11: =_xlfn.IFNA(VLOOKUP($C11&","&J3,$C$34:$D$112,2,FALSE),"-1") -> -1 | K11: =_xlfn.IFNA(VLOOKUP($C11&","&K3,$C$34:$D$112,2,FALSE),"-1") -> -1 | L11: =_xlfn.IFNA(VLOOKUP($C11&","&L3,$C$34:$D$112,2,FALSE),"-1") -> -1 | ... AB11: =_xlfn.IFNA(VLOOKUP($C11&","&AB3,$C$34:$D$112,2,FALSE),"-1") -> -1
A12: 2 | B12: =ROW()-4 -> 8 | C12: JBC | D12: =DEC2HEX(B12) -> 8 | E12: =_xlfn.IFNA(VLOOKUP($C12&","&E3,$C$34:$D$112,2,FALSE),"-1") -> -1 | F12: =_xlfn.IFNA(VLOOKUP($C12&","&F3,$C$34:$D$112,2,FALSE),"-1") -> -1 | G12: =_xlfn.IFNA(VLOOKUP($C12&","&G3,$C$34:$D$112,2,FALSE),"-1") -> -1 | H12: =_xlfn.IFNA(VLOOKUP($C12&","&H3,$C$34:$D$112,2,FALSE),"-1") -> -1 | I12: =_xlfn.IFNA(VLOOKUP($C12&","&I3,$C$34:$D$112,2,FALSE),"-1") -> -1 | J12: =_xlfn.IFNA(VLOOKUP($C12&","&J3,$C$34:$D$112,2,FALSE),"-1") -> -1 | K12: =_xlfn.IFNA(VLOOKUP($C12&","&K3,$C$34:$D$112,2,FALSE),"-1") -> -1 | L12: =_xlfn.IFNA(VLOOKUP($C12&","&L3,$C$34:$D$112,2,FALSE),"-1") -> -1 | ... AB12: =_xlfn.IFNA(VLOOKUP($C12&","&AB3,$C$34:$D$112,2,FALSE),"-1") -> -1
A13: 2 | B13: =ROW()-4 -> 9 | C13: JNB | D13: =DEC2HEX(B13) -> 9 | E13: =_xlfn.IFNA(VLOOKUP($C13&","&E3,$C$34:$D$112,2,FALSE),"-1") -> -1 | F13: =_xlfn.IFNA(VLOOKUP($C13&","&F3,$C$34:$D$112,2,FALSE),"-1") -> -1 | G13: =_xlfn.IFNA(VLOOKUP($C13&","&G3,$C$34:$D$112,2,FALSE),"-1") -> -1 | H13: =_xlfn.IFNA(VLOOKUP($C13&","&H3,$C$34:$D$112,2,FALSE),"-1") -> -1 | I13: =_xlfn.IFNA(VLOOKUP($C13&","&I3,$C$34:$D$112,2,FALSE),"-1") -> -1 | J13: =_xlfn.IFNA(VLOOKUP($C13&","&J3,$C$34:$D$112,2,FALSE),"-1") -> -1 | K13: =_xlfn.IFNA(VLOOKUP($C13&","&K3,$C$34:$D$112,2,FALSE),"-1") -> -1 | L13: =_xlfn.IFNA(VLOOKUP($C13&","&L3,$C$34:$D$112,2,FALSE),"-1") -> -1 | ... AB13: =_xlfn.IFNA(VLOOKUP($C13&","&AB3,$C$34:$D$112,2,FALSE),"-1") -> -1
A14: 2 | B14: =ROW()-4 -> 10 | C14: MOV | D14: =DEC2HEX(B14) -> A | E14: =_xlfn.IFNA(VLOOKUP($C14&","&E3,$C$34:$D$112,2,FALSE),"-1") -> 47 | F14: =_xlfn.IFNA(VLOOKUP($C14&","&F3,$C$34:$D$112,2,FALSE),"-1") -> 4C | G14: =_xlfn.IFNA(VLOOKUP($C14&","&G3,$C$34:$D$112,2,FALSE),"-1") -> 4D | H14: =_xlfn.IFNA(VLOOKUP($C14&","&H3,$C$34:$D$112,2,FALSE),"-1") -> 4E | I14: =_xlfn.IFNA(VLOOKUP($C14&","&I3,$C$34:$D$112,2,FALSE),"-1") -> 4F | J14: =_xlfn.IFNA(VLOOKUP($C14&","&J3,$C$34:$D$112,2,FALSE),"-1") -> 50 | K14: =_xlfn.IFNA(VLOOKUP($C14&","&K3,$C$34:$D$112,2,FALSE),"-1") -> 51 | L14: =_xlfn.IFNA(VLOOKUP($C14&","&L3,$C$34:$D$112,2,FALSE),"-1") -> 52 | ... AB14: =_xlfn.IFNA(VLOOKUP($C14&","&AB3,$C$34:$D$112,2,FALSE),"-1") -> -1
A15: 2 | B15: =ROW()-4 -> 11 | C15: MOVC | D15: =DEC2HEX(B15) -> B | E15: =_xlfn.IFNA(VLOOKUP($C15&","&E3,$C$34:$D$112,2,FALSE),"-1") -> 54 | F15: =_xlfn.IFNA(VLOOKUP($C15&","&F3,$C$34:$D$112,2,FALSE),"-1") -> -1 | G15: =_xlfn.IFNA(VLOOKUP($C15&","&G3,$C$34:$D$112,2,FALSE),"-1") -> -1 | H15: =_xlfn.IFNA(VLOOKUP($C15&","&H3,$C$34:$D$112,2,FALSE),"-1") -> -1 | I15: =_xlfn.IFNA(VLOOKUP($C15&","&I3,$C$34:$D$112,2,FALSE),"-1") -> -1 | J15: =_xlfn.IFNA(VLOOKUP($C15&","&J3,$C$34:$D$112,2,FALSE),"-1") -> -1 | K15: =_xlfn.IFNA(VLOOKUP($C15&","&K3,$C$34:$D$112,2,FALSE),"-1") -> -1 | L15: =_xlfn.IFNA(VLOOKUP($C15&","&L3,$C$34:$D$112,2,FALSE),"-1") -> -1 | ... AB15: =_xlfn.IFNA(VLOOKUP($C15&","&AB3,$C$34:$D$112,2,FALSE),"-1") -> -1
A16: 2 | B16: =ROW()-4 -> 12 | C16: MOVX | D16: =DEC2HEX(B16) -> C | E16: =_xlfn.IFNA(VLOOKUP($C16&","&E3,$C$34:$D$112,2,FALSE),"-1") -> 58 | F16: =_xlfn.IFNA(VLOOKUP($C16&","&F3,$C$34:$D$112,2,FALSE),"-1") -> -1 | G16: =_xlfn.IFNA(VLOOKUP($C16&","&G3,$C$34:$D$112,2,FALSE),"-1") -> -1 | H16: =_xlfn.IFNA(VLOOKUP($C16&","&H3,$C$34:$D$112,2,FALSE),"-1") -> -1 | I16: =_xlfn.IFNA(VLOOKUP($C16&","&I3,$C$34:$D$112,2,FALSE),"-1") -> -1 | J16: =_xlfn.IFNA(VLOOKUP($C16&","&J3,$C$34:$D$112,2,FALSE),"-1") -> -1 | K16: =_xlfn.IFNA(VLOOKUP($C16&","&K3,$C$34:$D$112,2,FALSE),"-1") -> -1 | L16: =_xlfn.IFNA(VLOOKUP($C16&","&L3,$C$34:$D$112,2,FALSE),"-1") -> -1 | ... AB16: =_xlfn.IFNA(VLOOKUP($C16&","&AB3,$C$34:$D$112,2,FALSE),"-1") -> -1
A17: 2 | B17: =ROW()-4 -> 13 | C17: ORL | D17: =DEC2HEX(B17) -> D | E17: =_xlfn.IFNA(VLOOKUP($C17&","&E3,$C$34:$D$112,2,FALSE),"-1") -> 59 | F17: =_xlfn.IFNA(VLOOKUP($C17&","&F3,$C$34:$D$112,2,FALSE),"-1") -> -1 | G17: =_xlfn.IFNA(VLOOKUP($C17&","&G3,$C$34:$D$112,2,FALSE),"-1") -> -1 | H17: =_xlfn.IFNA(VLOOKUP($C17&","&H3,$C$34:$D$112,2,FALSE),"-1") -> -1 | I17: =_xlfn.IFNA(VLOOKUP($C17&","&I3,$C$34:$D$112,2,FALSE),"-1") -> -1 | J17: =_xlfn.IFNA(VLOOKUP($C17&","&J3,$C$34:$D$112,2,FALSE),"-1") -> -1 | K17: =_xlfn.IFNA(VLOOKUP($C17&","&K3,$C$34:$D$112,2,FALSE),"-1") -> -1 | L17: =_xlfn.IFNA(VLOOKUP($C17&","&L3,$C$34:$D$112,2,FALSE),"-1") -> -1 | ... AB17: =_xlfn.IFNA(VLOOKUP($C17&","&AB3,$C$34:$D$112,2,FALSE),"-1") -> -1
A18: 2 | B18: =ROW()-4 -> 14 | C18: SUBB | D18: =DEC2HEX(B18) -> E | E18: =_xlfn.IFNA(VLOOKUP($C18&","&E3,$C$34:$D$112,2,FALSE),"-1") -> 5C | F18: =_xlfn.IFNA(VLOOKUP($C18&","&F3,$C$34:$D$112,2,FALSE),"-1") -> -1 | G18: =_xlfn.IFNA(VLOOKUP($C18&","&G3,$C$34:$D$112,2,FALSE),"-1") -> -1 | H18: =_xlfn.IFNA(VLOOKUP($C18&","&H3,$C$34:$D$112,2,FALSE),"-1") -> -1 | I18: =_xlfn.IFNA(VLOOKUP($C18&","&I3,$C$34:$D$112,2,FALSE),"-1") -> -1 | J18: =_xlfn.IFNA(VLOOKUP($C18&","&J3,$C$34:$D$112,2,FALSE),"-1") -> -1 | K18: =_xlfn.IFNA(VLOOKUP($C18&","&K3,$C$34:$D$112,2,FALSE),"-1") -> -1 | L18: =_xlfn.IFNA(VLOOKUP($C18&","&L3,$C$34:$D$112,2,FALSE),"-1") -> -1 | ... AB18: =_xlfn.IFNA(VLOOKUP($C18&","&AB3,$C$34:$D$112,2,FALSE),"-1") -> -1
A19: 2 | B19: =ROW()-4 -> 15 | C19: XCH | D19: =DEC2HEX(B19) -> F | E19: =_xlfn.IFNA(VLOOKUP($C19&","&E3,$C$34:$D$112,2,FALSE),"-1") -> 5D | F19: =_xlfn.IFNA(VLOOKUP($C19&","&F3,$C$34:$D$112,2,FALSE),"-1") -> -1 | G19: =_xlfn.IFNA(VLOOKUP($C19&","&G3,$C$34:$D$112,2,FALSE),"-1") -> -1 | H19: =_xlfn.IFNA(VLOOKUP($C19&","&H3,$C$34:$D$112,2,FALSE),"-1") -> -1 | I19: =_xlfn.IFNA(VLOOKUP($C19&","&I3,$C$34:$D$112,2,FALSE),"-1") -> -1 | J19: =_xlfn.IFNA(VLOOKUP($C19&","&J3,$C$34:$D$112,2,FALSE),"-1") -> -1 | K19: =_xlfn.IFNA(VLOOKUP($C19&","&K3,$C$34:$D$112,2,FALSE),"-1") -> -1 | L19: =_xlfn.IFNA(VLOOKUP($C19&","&L3,$C$34:$D$112,2,FALSE),"-1") -> -1 | ... AB19: =_xlfn.IFNA(VLOOKUP($C19&","&AB3,$C$34:$D$112,2,FALSE),"-1") -> -1
A20: 2 | B20: =ROW()-4 -> 16 | C20: XCHD | D20: =DEC2HEX(B20) -> 10 | E20: =_xlfn.IFNA(VLOOKUP($C20&","&E3,$C$34:$D$112,2,FALSE),"-1") -> 5E | F20: =_xlfn.IFNA(VLOOKUP($C20&","&F3,$C$34:$D$112,2,FALSE),"-1") -> -1 | G20: =_xlfn.IFNA(VLOOKUP($C20&","&G3,$C$34:$D$112,2,FALSE),"-1") -> -1 | H20: =_xlfn.IFNA(VLOOKUP($C20&","&H3,$C$34:$D$112,2,FALSE),"-1") -> -1 | I20: =_xlfn.IFNA(VLOOKUP($C20&","&I3,$C$34:$D$112,2,FALSE),"-1") -> -1 | J20: =_xlfn.IFNA(VLOOKUP($C20&","&J3,$C$34:$D$112,2,FALSE),"-1") -> -1 | K20: =_xlfn.IFNA(VLOOKUP($C20&","&K3,$C$34:$D$112,2,FALSE),"-1") -> -1 | L20: =_xlfn.IFNA(VLOOKUP($C20&","&L3,$C$34:$D$112,2,FALSE),"-1") -> -1 | ... AB20: =_xlfn.IFNA(VLOOKUP($C20&","&AB3,$C$34:$D$112,2,FALSE),"-1") -> -1
A21: 2 | B21: =ROW()-4 -> 17 | C21: XRL | D21: =DEC2HEX(B21) -> 11 | E21: =_xlfn.IFNA(VLOOKUP($C21&","&E3,$C$34:$D$112,2,FALSE),"-1") -> 5F | F21: =_xlfn.IFNA(VLOOKUP($C21&","&F3,$C$34:$D$112,2,FALSE),"-1") -> -1 | G21: =_xlfn.IFNA(VLOOKUP($C21&","&G3,$C$34:$D$112,2,FALSE),"-1") -> -1 | H21: =_xlfn.IFNA(VLOOKUP($C21&","&H3,$C$34:$D$112,2,FALSE),"-1") -> -1 | I21: =_xlfn.IFNA(VLOOKUP($C21&","&I3,$C$34:$D$112,2,FALSE),"-1") -> -1 | J21: =_xlfn.IFNA(VLOOKUP($C21&","&J3,$C$34:$D$112,2,FALSE),"-1") -> -1 | K21: =_xlfn.IFNA(VLOOKUP($C21&","&K3,$C$34:$D$112,2,FALSE),"-1") -> -1 | L21: =_xlfn.IFNA(VLOOKUP($C21&","&L3,$C$34:$D$112,2,FALSE),"-1") -> -1 | ... AB21: =_xlfn.IFNA(VLOOKUP($C21&","&AB3,$C$34:$D$112,2,FALSE),"-1") -> -1
A22: 3 | B22: =ROW()-4 -> 18 | C22: CJNE | D22: =DEC2HEX(B22) -> 12 | E22: =_xlfn.IFNA(VLOOKUP($C22&","&E3,$C$23:$D$112,2,FALSE),"-1") -> 15 | F22: =_xlfn.IFNA(VLOOKUP($C22&","&F3,$C$23:$D$112,2,FALSE),"-1") -> 16 | G22: =_xlfn.IFNA(VLOOKUP($C22&","&G3,$C$23:$D$112,2,FALSE),"-1") -> 17 | H22: =_xlfn.IFNA(VLOOKUP($C22&","&H3,$C$23:$D$112,2,FALSE),"-1") -> 18 | I22: =_xlfn.IFNA(VLOOKUP($C22&","&I3,$C$23:$D$112,2,FALSE),"-1") -> 19 | J22: =_xlfn.IFNA(VLOOKUP($C22&","&J3,$C$23:$D$112,2,FALSE),"-1") -> 1A | K22: =_xlfn.IFNA(VLOOKUP($C22&","&K3,$C$23:$D$112,2,FALSE),"-1") -> 1B | L22: =_xlfn.IFNA(VLOOKUP($C22&","&L3,$C$23:$D$112,2,FALSE),"-1") -> 1C | ... AB22: =_xlfn.IFNA(VLOOKUP($C22&","&AB3,$C$23:$D$112,2,FALSE),"-1") -> -1
A23: 3 | B23: =ROW()-4 -> 19 | C23: CJNE,@R0 | D23: =DEC2HEX(B23) -> 13 | E23: =_xlfn.IFNA(VLOOKUP($C23&","&E3,$C$34:$D$112,2,FALSE),"-1") -> -1 | F23: =_xlfn.IFNA(VLOOKUP($C23&","&F3,$C$34:$D$112,2,FALSE),"-1") -> -1 | G23: =_xlfn.IFNA(VLOOKUP($C23&","&G3,$C$34:$D$112,2,FALSE),"-1") -> -1 | H23: =_xlfn.IFNA(VLOOKUP($C23&","&H3,$C$34:$D$112,2,FALSE),"-1") -> -1 | I23: =_xlfn.IFNA(VLOOKUP($C23&","&I3,$C$34:$D$112,2,FALSE),"-1") -> -1 | J23: =_xlfn.IFNA(VLOOKUP($C23&","&J3,$C$34:$D$112,2,FALSE),"-1") -> -1 | K23: =_xlfn.IFNA(VLOOKUP($C23&","&K3,$C$34:$D$112,2,FALSE),"-1") -> -1 | L23: =_xlfn.IFNA(VLOOKUP($C23&","&L3,$C$34:$D$112,2,FALSE),"-1") -> -1 | ... AB23: =_xlfn.IFNA(VLOOKUP($C23&","&AB3,$C$34:$D$112,2,FALSE),"-1") -> -1
A24: 3 | B24: =ROW()-4 -> 20 | C24: CJNE,@R1 | D24: =DEC2HEX(B24) -> 14 | E24: =_xlfn.IFNA(VLOOKUP($C24&","&E3,$C$34:$D$112,2,FALSE),"-1") -> -1 | F24: =_xlfn.IFNA(VLOOKUP($C24&","&F3,$C$34:$D$112,2,FALSE),"-1") -> -1 | G24: =_xlfn.IFNA(VLOOKUP($C24&","&G3,$C$34:$D$112,2,FALSE),"-1") -> -1 | H24: =_xlfn.IFNA(VLOOKUP($C24&","&H3,$C$34:$D$112,2,FALSE),"-1") -> -1 | I24: =_xlfn.IFNA(VLOOKUP($C24&","&I3,$C$34:$D$112,2,FALSE),"-1") -> -1 | J24: =_xlfn.IFNA(VLOOKUP($C24&","&J3,$C$34:$D$112,2,FALSE),"-1") -> -1 | K24: =_xlfn.IFNA(VLOOKUP($C24&","&K3,$C$34:$D$112,2,FALSE),"-1") -> -1 | L24: =_xlfn.IFNA(VLOOKUP($C24&","&L3,$C$34:$D$112,2,FALSE),"-1") -> -1 | ... AB24: =_xlfn.IFNA(VLOOKUP($C24&","&AB3,$C$34:$D$112,2,FALSE),"-1") -> -1
A25: 3 | B25: =ROW()-4 -> 21 | C25: CJNE,A | D25: =DEC2HEX(B25) -> 15 | E25: =_xlfn.IFNA(VLOOKUP($C25&","&E3,$C$34:$D$112,2,FALSE),"-1") -> -1 | F25: =_xlfn.IFNA(VLOOKUP($C25&","&F3,$C$34:$D$112,2,FALSE),"-1") -> -1 | G25: =_xlfn.IFNA(VLOOKUP($C25&","&G3,$C$34:$D$112,2,FALSE),"-1") -> -1 | H25: =_xlfn.IFNA(VLOOKUP($C25&","&H3,$C$34:$D$112,2,FALSE),"-1") -> -1 | I25: =_xlfn.IFNA(VLOOKUP($C25&","&I3,$C$34:$D$112,2,FALSE),"-1") -> -1 | J25: =_xlfn.IFNA(VLOOKUP($C25&","&J3,$C$34:$D$112,2,FALSE),"-1") -> -1 | K25: =_xlfn.IFNA(VLOOKUP($C25&","&K3,$C$34:$D$112,2,FALSE),"-1") -> -1 | L25: =_xlfn.IFNA(VLOOKUP($C25&","&L3,$C$34:$D$112,2,FALSE),"-1") -> -1 | ... AB25: =_xlfn.IFNA(VLOOKUP($C25&","&AB3,$C$34:$D$112,2,FALSE),"-1") -> -1
A26: 3 | B26: =ROW()-4 -> 22 | C26: CJNE,R0 | D26: =DEC2HEX(B26) -> 16 | E26: =_xlfn.IFNA(VLOOKUP($C26&","&E3,$C$34:$D$112,2,FALSE),"-1") -> -1 | F26: =_xlfn.IFNA(VLOOKUP($C26&","&F3,$C$34:$D$112,2,FALSE),"-1") -> -1 | G26: =_xlfn.IFNA(VLOOKUP($C26&","&G3,$C$34:$D$112,2,FALSE),"-1") -> -1 | H26: =_xlfn.IFNA(VLOOKUP($C26&","&H3,$C$34:$D$112,2,FALSE),"-1") -> -1 | I26: =_xlfn.IFNA(VLOOKUP($C26&","&I3,$C$34:$D$112,2,FALSE),"-1") -> -1 | J26: =_xlfn.IFNA(VLOOKUP($C26&","&J3,$C$34:$D$112,2,FALSE),"-1") -> -1 | K26: =_xlfn.IFNA(VLOOKUP($C26&","&K3,$C$34:$D$112,2,FALSE),"-1") -> -1 | L26: =_xlfn.IFNA(VLOOKUP($C26&","&L3,$C$34:$D$112,2,FALSE),"-1") -> -1 | ... AB26: =_xlfn.IFNA(VLOOKUP($C26&","&AB3,$C$34:$D$112,2,FALSE),"-1") -> -1
A27: 3 | B27: =ROW()-4 -> 23 | C27: CJNE,R1 | D27: =DEC2HEX(B27) -> 17 | E27: =_xlfn.IFNA(VLOOKUP($C27&","&E3,$C$34:$D$112,2,FALSE),"-1") -> -1 | F27: =_xlfn.IFNA(VLOOKUP($C27&","&F3,$C$34:$D$112,2,FALSE),"-1") -> -1 | G27: =_xlfn.IFNA(VLOOKUP($C27&","&G3,$C$34:$D$112,2,FALSE),"-1") -> -1 | H27: =_xlfn.IFNA(VLOOKUP($C27&","&H3,$C$34:$D$112,2,FALSE),"-1") -> -1 | I27: =_xlfn.IFNA(VLOOKUP($C27&","&I3,$C$34:$D$112,2,FALSE),"-1") -> -1 | J27: =_xlfn.IFNA(VLOOKUP($C27&","&J3,$C$34:$D$112,2,FALSE),"-1") -> -1 | K27: =_xlfn.IFNA(VLOOKUP($C27&","&K3,$C$34:$D$112,2,FALSE),"-1") -> -1 | L27: =_xlfn.IFNA(VLOOKUP($C27&","&L3,$C$34:$D$112,2,FALSE),"-1") -> -1 | ... AB27: =_xlfn.IFNA(VLOOKUP($C27&","&AB3,$C$34:$D$112,2,FALSE),"-1") -> -1
A28: 3 | B28: =ROW()-4 -> 24 | C28: CJNE,R2 | D28: =DEC2HEX(B28) -> 18 | E28: =_xlfn.IFNA(VLOOKUP($C28&","&E3,$C$34:$D$112,2,FALSE),"-1") -> -1 | F28: =_xlfn.IFNA(VLOOKUP($C28&","&F3,$C$34:$D$112,2,FALSE),"-1") -> -1 | G28: =_xlfn.IFNA(VLOOKUP($C28&","&G3,$C$34:$D$112,2,FALSE),"-1") -> -1 | H28: =_xlfn.IFNA(VLOOKUP($C28&","&H3,$C$34:$D$112,2,FALSE),"-1") -> -1 | I28: =_xlfn.IFNA(VLOOKUP($C28&","&I3,$C$34:$D$112,2,FALSE),"-1") -> -1 | J28: =_xlfn.IFNA(VLOOKUP($C28&","&J3,$C$34:$D$112,2,FALSE),"-1") -> -1 | K28: =_xlfn.IFNA(VLOOKUP($C28&","&K3,$C$34:$D$112,2,FALSE),"-1") -> -1 | L28: =_xlfn.IFNA(VLOOKUP($C28&","&L3,$C$34:$D$112,2,FALSE),"-1") -> -1 | ... AB28: =_xlfn.IFNA(VLOOKUP($C28&","&AB3,$C$34:$D$112,2,FALSE),"-1") -> -1
A29: 3 | B29: =ROW()-4 -> 25 | C29: CJNE,R3 | D29: =DEC2HEX(B29) -> 19 | E29: =_xlfn.IFNA(VLOOKUP($C29&","&E3,$C$34:$D$112,2,FALSE),"-1") -> -1 | F29: =_xlfn.IFNA(VLOOKUP($C29&","&F3,$C$34:$D$112,2,FALSE),"-1") -> -1 | G29: =_xlfn.IFNA(VLOOKUP($C29&","&G3,$C$34:$D$112,2,FALSE),"-1") -> -1 | H29: =_xlfn.IFNA(VLOOKUP($C29&","&H3,$C$34:$D$112,2,FALSE),"-1") -> -1 | I29: =_xlfn.IFNA(VLOOKUP($C29&","&I3,$C$34:$D$112,2,FALSE),"-1") -> -1 | J29: =_xlfn.IFNA(VLOOKUP($C29&","&J3,$C$34:$D$112,2,FALSE),"-1") -> -1 | K29: =_xlfn.IFNA(VLOOKUP($C29&","&K3,$C$34:$D$112,2,FALSE),"-1") -> -1 | L29: =_xlfn.IFNA(VLOOKUP($C29&","&L3,$C$34:$D$112,2,FALSE),"-1") -> -1 | ... AB29: =_xlfn.IFNA(VLOOKUP($C29&","&AB3,$C$34:$D$112,2,FALSE),"-1") -> -1
A30: 3 | B30: =ROW()-4 -> 26 | C30: CJNE,R4 | D30: =DEC2HEX(B30) -> 1A | E30: =_xlfn.IFNA(VLOOKUP($C30&","&E3,$C$34:$D$112,2,FALSE),"-1") -> -1 | F30: =_xlfn.IFNA(VLOOKUP($C30&","&F3,$C$34:$D$112,2,FALSE),"-1") -> -1 | G30: =_xlfn.IFNA(VLOOKUP($C30&","&G3,$C$34:$D$112,2,FALSE),"-1") -> -1 | H30: =_xlfn.IFNA(VLOOKUP($C30&","&H3,$C$34:$D$112,2,FALSE),"-1") -> -1 | I30: =_xlfn.IFNA(VLOOKUP($C30&","&I3,$C$34:$D$112,2,FALSE),"-1") -> -1 | J30: =_xlfn.IFNA(VLOOKUP($C30&","&J3,$C$34:$D$112,2,FALSE),"-1") -> -1 | K30: =_xlfn.IFNA(VLOOKUP($C30&","&K3,$C$34:$D$112,2,FALSE),"-1") -> -1 | L30: =_xlfn.IFNA(VLOOKUP($C30&","&L3,$C$34:$D$112,2,FALSE),"-1") -> -1 | ... AB30: =_xlfn.IFNA(VLOOKUP($C30&","&AB3,$C$34:$D$112,2,FALSE),"-1") -> -1
A31: 3 | B31: =ROW()-4 -> 27 | C31: CJNE,R5 | D31: =DEC2HEX(B31) -> 1B | E31: =_xlfn.IFNA(VLOOKUP($C31&","&E3,$C$34:$D$112,2,FALSE),"-1") -> -1 | F31: =_xlfn.IFNA(VLOOKUP($C31&","&F3,$C$34:$D$112,2,FALSE),"-1") -> -1 | G31: =_xlfn.IFNA(VLOOKUP($C31&","&G3,$C$34:$D$112,2,FALSE),"-1") -> -1 | H31: =_xlfn.IFNA(VLOOKUP($C31&","&H3,$C$34:$D$112,2,FALSE),"-1") -> -1 | I31: =_xlfn.IFNA(VLOOKUP($C31&","&I3,$C$34:$D$112,2,FALSE),"-1") -> -1 | J31: =_xlfn.IFNA(VLOOKUP($C31&","&J3,$C$34:$D$112,2,FALSE),"-1") -> -1 | K31: =_xlfn.IFNA(VLOOKUP($C31&","&K3,$C$34:$D$112,2,FALSE),"-1") -> -1 | L31: =_xlfn.IFNA(VLOOKUP($C31&","&L3,$C$34:$D$112,2,FALSE),"-1") -> -1 | ... AB31: =_xlfn.IFNA(VLOOKUP($C31&","&AB3,$C$34:$D$112,2,FALSE),"-1") -> -1
A32: 3 | B32: =ROW()-4 -> 28 | C32: CJNE,R6 | D32: =DEC2HEX(B32) -> 1C | E32: =_xlfn.IFNA(VLOOKUP($C32&","&E3,$C$34:$D$112,2,FALSE),"-1") -> -1 | F32: =_xlfn.IFNA(VLOOKUP($C32&","&F3,$C$34:$D$112,2,FALSE),"-1") -> -1 | G32: =_xlfn.IFNA(VLOOKUP($C32&","&G3,$C$34:$D$112,2,FALSE),"-1") -> -1 | H32: =_xlfn.IFNA(VLOOKUP($C32&","&H3,$C$34:$D$112,2,FALSE),"-1") -> -1 | I32: =_xlfn.IFNA(VLOOKUP($C32&","&I3,$C$34:$D$112,2,FALSE),"-1") -> -1 | J32: =_xlfn.IFNA(VLOOKUP($C32&","&J3,$C$34:$D$112,2,FALSE),"-1") -> -1 | K32: =_xlfn.IFNA(VLOOKUP($C32&","&K3,$C$34:$D$112,2,FALSE),"-1") -> -1 | L32: =_xlfn.IFNA(VLOOKUP($C32&","&L3,$C$34:$D$112,2,FALSE),"-1") -> -1 | ... AB32: =_xlfn.IFNA(VLOOKUP($C32&","&AB3,$C$34:$D$112,2,FALSE),"-1") -> -1
A33: 3 | B33: =ROW()-4 -> 29 | C33: CJNE,R7 | D33: =DEC2HEX(B33) -> 1D | E33: =_xlfn.IFNA(VLOOKUP($C33&","&E3,$C$34:$D$112,2,FALSE),"-1") -> -1 | F33: =_xlfn.IFNA(VLOOKUP($C33&","&F3,$C$34:$D$112,2,FALSE),"-1") -> -1 | G33: =_xlfn.IFNA(VLOOKUP($C33&","&G3,$C$34:$D$112,2,FALSE),"-1") -> -1 | H33: =_xlfn.IFNA(VLOOKUP($C33&","&H3,$C$34:$D$112,2,FALSE),"-1") -> -1 | I33: =_xlfn.IFNA(VLOOKUP($C33&","&I3,$C$34:$D$112,2,FALSE),"-1") -> -1 | J33: =_xlfn.IFNA(VLOOKUP($C33&","&J3,$C$34:$D$112,2,FALSE),"-1") -> -1 | K33: =_xlfn.IFNA(VLOOKUP($C33&","&K3,$C$34:$D$112,2,FALSE),"-1") -> -1 | L33: =_xlfn.IFNA(VLOOKUP($C33&","&L3,$C$34:$D$112,2,FALSE),"-1") -> -1 | ... AB33: =_xlfn.IFNA(VLOOKUP($C33&","&AB3,$C$34:$D$112,2,FALSE),"-1") -> -1
A34: 1 | B34: =ROW()-4 -> 30 | C34: CLR | D34: =DEC2HEX(B34) -> 1E | E34: =_xlfn.IFNA(VLOOKUP($C34&","&E3,汇编指令!$C$2:$D$235,2,FALSE),"-1") -> E4 | F34: =_xlfn.IFNA(VLOOKUP($C34&","&F3,汇编指令!$C$2:$D$235,2,FALSE),"-1") -> -1 | G34: =_xlfn.IFNA(VLOOKUP($C34&","&G3,汇编指令!$C$2:$D$235,2,FALSE),"-1") -> -1 | H34: =_xlfn.IFNA(VLOOKUP($C34&","&H3,汇编指令!$C$2:$D$235,2,FALSE),"-1") -> -1 | I34: =_xlfn.IFNA(VLOOKUP($C34&","&I3,汇编指令!$C$2:$D$235,2,FALSE),"-1") -> -1 | J34: =_xlfn.IFNA(VLOOKUP($C34&","&J3,汇编指令!$C$2:$D$235,2,FALSE),"-1") -> -1 | K34: =_xlfn.IFNA(VLOOKUP($C34&","&K3,汇编指令!$C$2:$D$235,2,FALSE),"-1") -> -1 | L34: =_xlfn.IFNA(VLOOKUP($C34&","&L3,汇编指令!$C$2:$D$235,2,FALSE),"-1") -> -1 | ... AB34: =_xlfn.IFNA(VLOOKUP($C34&","&AB3,汇编指令!$C$2:$D$235,2,FALSE),"-1") -> -1
A35: 1 | B35: =ROW()-4 -> 31 | C35: CPL | D35: =DEC2HEX(B35) -> 1F | E35: =_xlfn.IFNA(VLOOKUP($C35&","&E3,汇编指令!$C$2:$D$235,2,FALSE),"-1") -> F4 | F35: =_xlfn.IFNA(VLOOKUP($C35&","&F3,汇编指令!$C$2:$D$235,2,FALSE),"-1") -> -1 | G35: =_xlfn.IFNA(VLOOKUP($C35&","&G3,汇编指令!$C$2:$D$235,2,FALSE),"-1") -> -1 | H35: =_xlfn.IFNA(VLOOKUP($C35&","&H3,汇编指令!$C$2:$D$235,2,FALSE),"-1") -> -1 | I35: =_xlfn.IFNA(VLOOKUP($C35&","&I3,汇编指令!$C$2:$D$235,2,FALSE),"-1") -> -1 | J35: =_xlfn.IFNA(VLOOKUP($C35&","&J3,汇编指令!$C$2:$D$235,2,FALSE),"-1") -> -1 | K35: =_xlfn.IFNA(VLOOKUP($C35&","&K3,汇编指令!$C$2:$D$235,2,FALSE),"-1") -> -1 | L35: =_xlfn.IFNA(VLOOKUP($C35&","&L3,汇编指令!$C$2:$D$235,2,FALSE),"-1") -> -1 | ... AB35: =_xlfn.IFNA(VLOOKUP($C35&","&AB3,汇编指令!$C$2:$D$235,2,FALSE),"-1") -> -1
A36: 1 | B36: =ROW()-4 -> 32 | C36: DA | D36: =DEC2HEX(B36) -> 20 | E36: =_xlfn.IFNA(VLOOKUP($C36&","&E3,汇编指令!$C$2:$D$235,2,FALSE),"-1") -> D4 | F36: =_xlfn.IFNA(VLOOKUP($C36&","&F3,汇编指令!$C$2:$D$235,2,FALSE),"-1") -> -1 | G36: =_xlfn.IFNA(VLOOKUP($C36&","&G3,汇编指令!$C$2:$D$235,2,FALSE),"-1") -> -1 | H36: =_xlfn.IFNA(VLOOKUP($C36&","&H3,汇编指令!$C$2:$D$235,2,FALSE),"-1") -> -1 | I36: =_xlfn.IFNA(VLOOKUP($C36&","&I3,汇编指令!$C$2:$D$235,2,FALSE),"-1") -> -1 | J36: =_xlfn.IFNA(VLOOKUP($C36&","&J3,汇编指令!$C$2:$D$235,2,FALSE),"-1") -> -1 | K36: =_xlfn.IFNA(VLOOKUP($C36&","&K3,汇编指令!$C$2:$D$235,2,FALSE),"-1") -> -1 | L36: =_xlfn.IFNA(VLOOKUP($C36&","&L3,汇编指令!$C$2:$D$235,2,FALSE),"-1") -> -1 | ... AB36: =_xlfn.IFNA(VLOOKUP($C36&","&AB3,汇编指令!$C$2:$D$235,2,FALSE),"-1") -> -1
A37: 1 | B37: =ROW()-4 -> 33 | C37: DEC | D37: =DEC2HEX(B37) -> 21 | E37: =_xlfn.IFNA(VLOOKUP($C37&","&E3,汇编指令!$C$2:$D$235,2,FALSE),"-1") -> 14 | F37: =_xlfn.IFNA(VLOOKUP($C37&","&F3,汇编指令!$C$2:$D$235,2,FALSE),"-1") -> 18 | G37: =_xlfn.IFNA(VLOOKUP($C37&","&G3,汇编指令!$C$2:$D$235,2,FALSE),"-1") -> 19 | H37: =_xlfn.IFNA(VLOOKUP($C37&","&H3,汇编指令!$C$2:$D$235,2,FALSE),"-1") -> 1A | I37: =_xlfn.IFNA(VLOOKUP($C37&","&I3,汇编指令!$C$2:$D$235,2,FALSE),"-1") -> 1B | J37: =_xlfn.IFNA(VLOOKUP($C37&","&J3,汇编指令!$C$2:$D$235,2,FALSE),"-1") -> 1C | K37: =_xlfn.IFNA(VLOOKUP($C37&","&K3,汇编指令!$C$2:$D$235,2,FALSE),"-1") -> 1D | L37: =_xlfn.IFNA(VLOOKUP($C37&","&L3,汇编指令!$C$2:$D$235,2,FALSE),"-1") -> 1E | ... AB37: =_xlfn.IFNA(VLOOKUP($C37&","&AB3,汇编指令!$C$2:$D$235,2,FALSE),"-1") -> -1
A38: 1 | B38: =ROW()-4 -> 34 | C38: DIV | D38: =DEC2HEX(B38) -> 22 | E38: =_xlfn.IFNA(VLOOKUP($C38&","&E3,汇编指令!$C$2:$D$235,2,FALSE),"-1") -> -1 | F38: =_xlfn.IFNA(VLOOKUP($C38&","&F3,汇编指令!$C$2:$D$235,2,FALSE),"-1") -> -1 | G38: =_xlfn.IFNA(VLOOKUP($C38&","&G3,汇编指令!$C$2:$D$235,2,FALSE),"-1") -> -1 | H38: =_xlfn.IFNA(VLOOKUP($C38&","&H3,汇编指令!$C$2:$D$235,2,FALSE),"-1") -> -1 | I38: =_xlfn.IFNA(VLOOKUP($C38&","&I3,汇编指令!$C$2:$D$235,2,FALSE),"-1") -> -1 | J38: =_xlfn.IFNA(VLOOKUP($C38&","&J3,汇编指令!$C$2:$D$235,2,FALSE),"-1") -> -1 | K38: =_xlfn.IFNA(VLOOKUP($C38&","&K3,汇编指令!$C$2:$D$235,2,FALSE),"-1") -> -1 | L38: =_xlfn.IFNA(VLOOKUP($C38&","&L3,汇编指令!$C$2:$D$235,2,FALSE),"-1") -> -1 | ... AB38: =_xlfn.IFNA(VLOOKUP($C38&","&AB3,汇编指令!$C$2:$D$235,2,FALSE),"-1") -> -1
A39: 1 | B39: =ROW()-4 -> 35 | C39: INC | D39: =DEC2HEX(B39) -> 23 | E39: =_xlfn.IFNA(VLOOKUP($C39&","&E3,汇编指令!$C$2:$D$235,2,FALSE),"-1") -> 4 | F39: =_xlfn.IFNA(VLOOKUP($C39&","&F3,汇编指令!$C$2:$D$235,2,FALSE),"-1") -> 8 | G39: =_xlfn.IFNA(VLOOKUP($C39&","&G3,汇编指令!$C$2:$D$235,2,FALSE),"-1") -> 9 | H39: =_xlfn.IFNA(VLOOKUP($C39&","&H3,汇编指令!$C$2:$D$235,2,FALSE),"-1") -> A | I39: =_xlfn.IFNA(VLOOKUP($C39&","&I3,汇编指令!$C$2:$D$235,2,FALSE),"-1") -> B | J39: =_xlfn.IFNA(VLOOKUP($C39&","&J3,汇编指令!$C$2:$D$235,2,FALSE),"-1") -> C | K39: =_xlfn.IFNA(VLOOKUP($C39&","&K3,汇编指令!$C$2:$D$235,2,FALSE),"-1") -> D | L39: =_xlfn.IFNA(VLOOKUP($C39&","&L3,汇编指令!$C$2:$D$235,2,FALSE),"-1") -> E | ... AB39: =_xlfn.IFNA(VLOOKUP($C39&","&AB3,汇编指令!$C$2:$D$235,2,FALSE),"-1") -> -1
A40: 1 | B40: =ROW()-4 -> 36 | C40: JC | D40: =DEC2HEX(B40) -> 24 | E40: =_xlfn.IFNA(VLOOKUP($C40&","&E3,汇编指令!$C$2:$D$235,2,FALSE),"-1") -> -1 | F40: =_xlfn.IFNA(VLOOKUP($C40&","&F3,汇编指令!$C$2:$D$235,2,FALSE),"-1") -> -1 | G40: =_xlfn.IFNA(VLOOKUP($C40&","&G3,汇编指令!$C$2:$D$235,2,FALSE),"-1") -> -1 | H40: =_xlfn.IFNA(VLOOKUP($C40&","&H3,汇编指令!$C$2:$D$235,2,FALSE),"-1") -> -1 | I40: =_xlfn.IFNA(VLOOKUP($C40&","&I3,汇编指令!$C$2:$D$235,2,FALSE),"-1") -> -1 | J40: =_xlfn.IFNA(VLOOKUP($C40&","&J3,汇编指令!$C$2:$D$235,2,FALSE),"-1") -> -1 | K40: =_xlfn.IFNA(VLOOKUP($C40&","&K3,汇编指令!$C$2:$D$235,2,FALSE),"-1") -> -1 | L40: =_xlfn.IFNA(VLOOKUP($C40&","&L3,汇编指令!$C$2:$D$235,2,FALSE),"-1") -> -1 | ... AB40: =_xlfn.IFNA(VLOOKUP($C40&","&AB3,汇编指令!$C$2:$D$235,2,FALSE),"-1") -> -1
...

Sheet 汇编指令字节数表
A1: direct 表示直接寻址（00H-FFH），#data 表示立即数（00H-FFH），#data16 表示16位立即数（0000H-FFFFH） rel 表示相对地址（-128~127），addr11 表示11位地址（0000H-07FFH），addr16 表示16位地址（0000H-FFFFH）
E2: =COLUMN()-3 -> 2 | F2: =COLUMN()-3 -> 3 | G2: =COLUMN()-3 -> 4 | H2: =COLUMN()-3 -> 5 | I2: =COLUMN()-3 -> 6 | J2: =COLUMN()-3 -> 7 | K2: =COLUMN()-3 -> 8 | L2: =COLUMN()-3 -> 9 | ... AB2: =COLUMN()-3 -> 25
A3: 参数个数 | C3: 命令 | E3: A | F3: R0 | G3: R1 | H3: R2 | I3: R3 | J3: R4 | K3: R5 | L3: R6 | M3: R7 | N3: #data | O3: direct | P3: @R0 | Q3: @R1 | R3: DPTR | S3: #data16 | T3: @A+PC | U3: @A+DPTR | V3: @DPTR | W3: addr16 | X3: rel | Y3: bit | Z3: C | AA3: AB | AB3: /bit
A4: 0 | B4: =ROW()-4 -> 0 | C4: NOP | D4: =DEC2HEX(B4) -> 0 | E4: =_xlfn.IFNA(VLOOKUP($C4&","&E3,$C$69:$D$112,2,FALSE),"-1") -> -1 | F4: =_xlfn.IFNA(VLOOKUP($C4&","&F3,$C$69:$D$112,2,FALSE),"-1") -> -1 | G4: =_xlfn.IFNA(VLOOKUP($C4&","&G3,$C$69:$D$112,2,FALSE),"-1") -> -1 | H4: =_xlfn.IFNA(VLOOKUP($C4&","&H3,$C$69:$D$112,2,FALSE),"-1") -> -1 | I4: =_xlfn.IFNA(VLOOKUP($C4&","&I3,$C$69:$D$112,2,FALSE),"-1") -> -1 | J4: =_xlfn.IFNA(VLOOKUP($C4&","&J3,$C$69:$D$112,2,FALSE),"-1") -> -1 | K4: =_xlfn.IFNA(VLOOKUP($C4&","&K3,$C$69:$D$112,2,FALSE),"-1") -> -1 | L4: =_xlfn.IFNA(VLOOKUP($C4&","&L3,$C$69:$D$112,2,FALSE),"-1") -> -1 | ... AB4: =_xlfn.IFNA(VLOOKUP($C4&","&AB3,$C$69:$D$112,2,FALSE),"-1") -> -1 | AC4: 0
A5: 0 | B5: =ROW()-4 -> 1 | C5: RET | D5: =DEC2HEX(B5) -> 1 | E5: =_xlfn.IFNA(VLOOKUP($C5&","&E3,$C$69:$D$112,2,FALSE),"-1") -> -1 | F5: =_xlfn.IFNA(VLOOKUP($C5&","&F3,$C$69:$D$112,2,FALSE),"-1") -> -1 | G5: =_xlfn.IFNA(VLOOKUP($C5&","&G3,$C$69:$D$112,2,FALSE),"-1") -> -1 | H5: =_xlfn.IFNA(VLOOKUP($C5&","&H3,$C$69:$D$112,2,FALSE),"-1") -> -1 | I5: =_xlfn.IFNA(VLOOKUP($C5&","&I3,$C$69:$D$112,2,FALSE),"-1") -> -1 | J5: =_xlfn.IFNA(VLOOKUP($C5&","&J3,$C$69:$D$112,2,FALSE),"-1") -> -1 | K5: =_xlfn.IFNA(VLOOKUP($C5&","&K3,$C$69:$D$112,2,FALSE),"-1") -> -1 | L5: =_xlfn.IFNA(VLOOKUP($C5&","&L3,$C$69:$D$112,2,FALSE),"-1") -> -1 | ... AB5: =_xlfn.IFNA(VLOOKUP($C5&","&AB3,$C$69:$D$112,2,FALSE),"-1") -> -1 | AC5: 22
A6: 0 | B6: =ROW()-4 -> 2 | C6: RETI | D6: =DEC2HEX(B6) -> 2 | E6: =_xlfn.IFNA(VLOOKUP($C6&","&E3,$C$69:$D$112,2,FALSE),"-1") -> -1 | F6: =_xlfn.IFNA(VLOOKUP($C6&","&F3,$C$69:$D$112,2,FALSE),"-1") -> -1 | G6: =_xlfn.IFNA(VLOOKUP($C6&","&G3,$C$69:$D$112,2,FALSE),"-1") -> -1 | H6: =_xlfn.IFNA(VLOOKUP($C6&","&H3,$C$69:$D$112,2,FALSE),"-1") -> -1 | I6: =_xlfn.IFNA(VLOOKUP($C6&","&I3,$C$69:$D$112,2,FALSE),"-1") -> -1 | J6: =_xlfn.IFNA(VLOOKUP($C6&","&J3,$C$69:$D$112,2,FALSE),"-1") -> -1 | K6: =_xlfn.IFNA(VLOOKUP($C6&","&K3,$C$69:$D$112,2,FALSE),"-1") -> -1 | L6: =_xlfn.IFNA(VLOOKUP($C6&","&L3,$C$69:$D$112,2,FALSE),"-1") -> -1 | ... AB6: =_xlfn.IFNA(VLOOKUP($C6&","&AB3,$C$69:$D$112,2,FALSE),"-1") -> -1 | AC6: 32
A7: 2 | B7: =ROW()-4 -> 3 | C7: ADD | D7: =DEC2HEX(B7) -> 3 | E7: =_xlfn.IFNA(VLOOKUP($C7&","&E3,$C$34:$D$112,2,FALSE),"-1") -> 35 | F7: =_xlfn.IFNA(VLOOKUP($C7&","&F3,$C$34:$D$112,2,FALSE),"-1") -> -1 | G7: =_xlfn.IFNA(VLOOKUP($C7&","&G3,$C$34:$D$112,2,FALSE),"-1") -> -1 | H7: =_xlfn.IFNA(VLOOKUP($C7&","&H3,$C$34:$D$112,2,FALSE),"-1") -> -1 | I7: =_xlfn.IFNA(VLOOKUP($C7&","&I3,$C$34:$D$112,2,FALSE),"-1") -> -1 | J7: =_xlfn.IFNA(VLOOKUP($C7&","&J3,$C$34:$D$112,2,FALSE),"-1") -> -1 | K7: =_xlfn.IFNA(VLOOKUP($C7&","&K3,$C$34:$D$112,2,FALSE),"-1") -> -1 | L7: =_xlfn.IFNA(VLOOKUP($C7&","&L3,$C$34:$D$112,2,FALSE),"-1") -> -1 | ... AB7: =_xlfn.IFNA(VLOOKUP($C7&","&AB3,$C$34:$D$112,2,FALSE),"-1") -> -1
A8: 2 | B8: =ROW()-4 -> 4 | C8: ADDC | D8: =DEC2HEX(B8) -> 4 | E8: =_xlfn.IFNA(VLOOKUP($C8&","&E3,$C$34:$D$112,2,FALSE),"-1") -> 36 | F8: =_xlfn.IFNA(VLOOKUP($C8&","&F3,$C$34:$D$112,2,FALSE),"-1") -> -1 | G8: =_xlfn.IFNA(VLOOKUP($C8&","&G3,$C$34:$D$112,2,FALSE),"-1") -> -1 | H8: =_xlfn.IFNA(VLOOKUP($C8&","&H3,$C$34:$D$112,2,FALSE),"-1") -> -1 | I8: =_xlfn.IFNA(VLOOKUP($C8&","&I3,$C$34:$D$112,2,FALSE),"-1") -> -1 | J8: =_xlfn.IFNA(VLOOKUP($C8&","&J3,$C$34:$D$112,2,FALSE),"-1") -> -1 | K8: =_xlfn.IFNA(VLOOKUP($C8&","&K3,$C$34:$D$112,2,FALSE),"-1") -> -1 | L8: =_xlfn.IFNA(VLOOKUP($C8&","&L3,$C$34:$D$112,2,FALSE),"-1") -> -1 | ... AB8: =_xlfn.IFNA(VLOOKUP($C8&","&AB3,$C$34:$D$112,2,FALSE),"-1") -> -1
A9: 2 | B9: =ROW()-4 -> 5 | C9: ANL | D9: =DEC2HEX(B9) -> 5 | E9: =_xlfn.IFNA(VLOOKUP($C9&","&E3,$C$34:$D$112,2,FALSE),"-1") -> 37 | F9: =_xlfn.IFNA(VLOOKUP($C9&","&F3,$C$34:$D$112,2,FALSE),"-1") -> -1 | G9: =_xlfn.IFNA(VLOOKUP($C9&","&G3,$C$34:$D$112,2,FALSE),"-1") -> -1 | H9: =_xlfn.IFNA(VLOOKUP($C9&","&H3,$C$34:$D$112,2,FALSE),"-1") -> -1 | I9: =_xlfn.IFNA(VLOOKUP($C9&","&I3,$C$34:$D$112,2,FALSE),"-1") -> -1 | J9: =_xlfn.IFNA(VLOOKUP($C9&","&J3,$C$34:$D$112,2,FALSE),"-1") -> -1 | K9: =_xlfn.IFNA(VLOOKUP($C9&","&K3,$C$34:$D$112,2,FALSE),"-1") -> -1 | L9: =_xlfn.IFNA(VLOOKUP($C9&","&L3,$C$34:$D$112,2,FALSE),"-1") -> -1 | ... AB9: =_xlfn.IFNA(VLOOKUP($C9&","&AB3,$C$34:$D$112,2,FALSE),"-1") -> -1
A10: 2 | B10: =ROW()-4 -> 6 | C10: DJNZ | D10: =DEC2HEX(B10) -> 6 | E10: =_xlfn.IFNA(VLOOKUP($C10&","&E3,$C$34:$D$112,2,FALSE),"-1") -> -1 | F10: =_xlfn.IFNA(VLOOKUP($C10&","&F3,$C$34:$D$112,2,FALSE),"-1") -> 3A | G10: =_xlfn.IFNA(VLOOKUP($C10&","&G3,$C$34:$D$112,2,FALSE),"-1") -> 3B | H10: =_xlfn.IFNA(VLOOKUP($C10&","&H3,$C$34:$D$112,2,FALSE),"-1") -> 3C | I10: =_xlfn.IFNA(VLOOKUP($C10&","&I3,$C$34:$D$112,2,FALSE),"-1") -> 3D | J10: =_xlfn.IFNA(VLOOKUP($C10&","&J3,$C$34:$D$112,2,FALSE),"-1") -> 3E | K10: =_xlfn.IFNA(VLOOKUP($C10&","&K3,$C$34:$D$112,2,FALSE),"-1") -> 3F | L10: =_xlfn.IFNA(VLOOKUP($C10&","&L3,$C$34:$D$112,2,FALSE),"-1") -> 40 | ... AB10: =_xlfn.IFNA(VLOOKUP($C10&","&AB3,$C$34:$D$112,2,FALSE),"-1") -> -1
A11: 2 | B11: =ROW()-4 -> 7 | C11: JB | D11: =DEC2HEX(B11) -> 7 | E11: =_xlfn.IFNA(VLOOKUP($C11&","&E3,$C$34:$D$112,2,FALSE),"-1") -> -1 | F11: =_xlfn.IFNA(VLOOKUP($C11&","&F3,$C$34:$D$112,2,FALSE),"-1") -> -1 | G11: =_xlfn.IFNA(VLOOKUP($C11&","&G3,$C$34:$D$112,2,FALSE),"-1") -> -1 | H11: =_xlfn.IFNA(VLOOKUP($C11&","&H3,$C$34:$D$112,2,FALSE),"-1") -> -1 | I11: =_xlfn.IFNA(VLOOKUP($C11&","&I3,$C$34:$D$112,2,FALSE),"-1") -> -1 | J11: =_xlfn.IFNA(VLOOKUP($C11&","&J3,$C$34:$D$112,2,FALSE),"-1") -> -1 | K11: =_xlfn.IFNA(VLOOKUP($C11&","&K3,$C$34:$D$112,2,FALSE),"-1") -> -1 | L11: =_xlfn.IFNA(VLOOKUP($C11&","&L3,$C$34:$D$112,2,FALSE),"-1") -> -1 | ... AB11: =_xlfn.IFNA(VLOOKUP($C11&","&AB3,$C$34:$D$112,2,FALSE),"-1") -> -1
A12: 2 | B12: =ROW()-4 -> 8 | C12: JBC | D12: =DEC2HEX(B12) -> 8 | E12: =_xlfn.IFNA(VLOOKUP($C12&","&E3,$C$34:$D$112,2,FALSE),"-1") -> -1 | F12: =_xlfn.IFNA(VLOOKUP($C12&","&F3,$C$34:$D$112,2,FALSE),"-1") -> -1 | G12: =_xlfn.IFNA(VLOOKUP($C12&","&G3,$C$34:$D$112,2,FALSE),"-1") -> -1 | H12: =_xlfn.IFNA(VLOOKUP($C12&","&H3,$C$34:$D$112,2,FALSE),"-1") -> -1 | I12: =_xlfn.IFNA(VLOOKUP($C12&","&I3,$C$34:$D$112,2,FALSE),"-1") -> -1 | J12: =_xlfn.IFNA(VLOOKUP($C12&","&J3,$C$34:$D$112,2,FALSE),"-1") -> -1 | K12: =_xlfn.IFNA(VLOOKUP($C12&","&K3,$C$34:$D$112,2,FALSE),"-1") -> -1 | L12: =_xlfn.IFNA(VLOOKUP($C12&","&L3,$C$34:$D$112,2,FALSE),"-1") -> -1 | ... AB12: =_xlfn.IFNA(VLOOKUP($C12&","&AB3,$C$34:$D$112,2,FALSE),"-1") -> -1
A13: 2 | B13: =ROW()-4 -> 9 | C13: JNB | D13: =DEC2HEX(B13) -> 9 | E13: =_xlfn.IFNA(VLOOKUP($C13&","&E3,$C$34:$D$112,2,FALSE),"-1") -> -1 | F13: =_xlfn.IFNA(VLOOKUP($C13&","&F3,$C$34:$D$112,2,FALSE),"-1") -> -1 | G13: =_xlfn.IFNA(VLOOKUP($C13&","&G3,$C$34:$D$112,2,FALSE),"-1") -> -1 | H13: =_xlfn.IFNA(VLOOKUP($C13&","&H3,$C$34:$D$112,2,FALSE),"-1") -> -1 | I13: =_xlfn.IFNA(VLOOKUP($C13&","&I3,$C$34:$D$112,2,FALSE),"-1") -> -1 | J13: =_xlfn.IFNA(VLOOKUP($C13&","&J3,$C$34:$D$112,2,FALSE),"-1") -> -1 | K13: =_xlfn.IFNA(VLOOKUP($C13&","&K3,$C$34:$D$112,2,FALSE),"-1") -> -1 | L13: =_xlfn.IFNA(VLOOKUP($C13&","&L3,$C$34:$D$112,2,FALSE),"-1") -> -1 | ... AB13: =_xlfn.IFNA(VLOOKUP($C13&","&AB3,$C$34:$D$112,2,FALSE),"-1") -> -1
A14: 2 | B14: =ROW()-4 -> 10 | C14: MOV | D14: =DEC2HEX(B14) -> A | E14: =_xlfn.IFNA(VLOOKUP($C14&","&E3,$C$34:$D$112,2,FALSE),"-1") -> 47 | F14: =_xlfn.IFNA(VLOOKUP($C14&","&F3,$C$34:$D$112,2,FALSE),"-1") -> 4C | G14: =_xlfn.IFNA(VLOOKUP($C14&","&G3,$C$34:$D$112,2,FALSE),"-1") -> 4D | H14: =_xlfn.IFNA(VLOOKUP($C14&","&H3,$C$34:$D$112,2,FALSE),"-1") -> 4E | I14: =_xlfn.IFNA(VLOOKUP($C14&","&I3,$C$34:$D$112,2,FALSE),"-1") -> 4F | J14: =_xlfn.IFNA(VLOOKUP($C14&","&J3,$C$34:$D$112,2,FALSE),"-1") -> 50 | K14: =_xlfn.IFNA(VLOOKUP($C14&","&K3,$C$34:$D$112,2,FALSE),"-1") -> 51 | L14: =_xlfn.IFNA(VLOOKUP($C14&","&L3,$C$34:$D$112,2,FALSE),"-1") -> 52 | ... AB14: =_xlfn.IFNA(VLOOKUP($C14&","&AB3,$C$34:$D$112,2,FALSE),"-1") -> -1
A15: 2 | B15: =ROW()-4 -> 11 | C15: MOVC | D15: =DEC2HEX(B15) -> B | E15: =_xlfn.IFNA(VLOOKUP($C15&","&E3,$C$34:$D$112,2,FALSE),"-1") -> 54 | F15: =_xlfn.IFNA(VLOOKUP($C15&","&F3,$C$34:$D$112,2,FALSE),"-1") -> -1 | G15: =_xlfn.IFNA(VLOOKUP($C15&","&G3,$C$34:$D$112,2,FALSE),"-1") -> -1 | H15: =_xlfn.IFNA(VLOOKUP($C15&","&H3,$C$34:$D$112,2,FALSE),"-1") -> -1 | I15: =_xlfn.IFNA(VLOOKUP($C15&","&I3,$C$34:$D$112,2,FALSE),"-1") -> -1 | J15: =_xlfn.IFNA(VLOOKUP($C15&","&J3,$C$34:$D$112,2,FALSE),"-1") -> -1 | K15: =_xlfn.IFNA(VLOOKUP($C15&","&K3,$C$34:$D$112,2,FALSE),"-1") -> -1 | L15: =_xlfn.IFNA(VLOOKUP($C15&","&L3,$C$34:$D$112,2,FALSE),"-1") -> -1 | ... AB15: =_xlfn.IFNA(VLOOKUP($C15&","&AB3,$C$34:$D$112,2,FALSE),"-1") -> -1
A16: 2 | B16: =ROW()-4 -> 12 | C16: MOVX | D16: =DEC2HEX(B16) -> C | E16: =_xlfn.IFNA(VLOOKUP($C16&","&E3,$C$34:$D$112,2,FALSE),"-1") -> 58 | F16: =_xlfn.IFNA(VLOOKUP($C16&","&F3,$C$34:$D$112,2,FALSE),"-1") -> -1 | G16: =_xlfn.IFNA(VLOOKUP($C16&","&G3,$C$34:$D$112,2,FALSE),"-1") -> -1 | H16: =_xlfn.IFNA(VLOOKUP($C16&","&H3,$C$34:$D$112,2,FALSE),"-1") -> -1 | I16: =_xlfn.IFNA(VLOOKUP($C16&","&I3,$C$34:$D$112,2,FALSE),"-1") -> -1 | J16: =_xlfn.IFNA(VLOOKUP($C16&","&J3,$C$34:$D$112,2,FALSE),"-1") -> -1 | K16: =_xlfn.IFNA(VLOOKUP($C16&","&K3,$C$34:$D$112,2,FALSE),"-1") -> -1 | L16: =_xlfn.IFNA(VLOOKUP($C16&","&L3,$C$34:$D$112,2,FALSE),"-1") -> -1 | ... AB16: =_xlfn.IFNA(VLOOKUP($C16&","&AB3,$C$34:$D$112,2,FALSE),"-1") -> -1
A17: 2 | B17: =ROW()-4 -> 13 | C17: ORL | D17: =DEC2HEX(B17) -> D | E17: =_xlfn.IFNA(VLOOKUP($C17&","&E3,$C$34:$D$112,2,FALSE),"-1") -> 59 | F17: =_xlfn.IFNA(VLOOKUP($C17&","&F3,$C$34:$D$112,2,FALSE),"-1") -> -1 | G17: =_xlfn.IFNA(VLOOKUP($C17&","&G3,$C$34:$D$112,2,FALSE),"-1") -> -1 | H17: =_xlfn.IFNA(VLOOKUP($C17&","&H3,$C$34:$D$112,2,FALSE),"-1") -> -1 | I17: =_xlfn.IFNA(VLOOKUP($C17&","&I3,$C$34:$D$112,2,FALSE),"-1") -> -1 | J17: =_xlfn.IFNA(VLOOKUP($C17&","&J3,$C$34:$D$112,2,FALSE),"-1") -> -1 | K17: =_xlfn.IFNA(VLOOKUP($C17&","&K3,$C$34:$D$112,2,FALSE),"-1") -> -1 | L17: =_xlfn.IFNA(VLOOKUP($C17&","&L3,$C$34:$D$112,2,FALSE),"-1") -> -1 | ... AB17: =_xlfn.IFNA(VLOOKUP($C17&","&AB3,$C$34:$D$112,2,FALSE),"-1") -> -1
A18: 2 | B18: =ROW()-4 -> 14 | C18: SUBB | D18: =DEC2HEX(B18) -> E | E18: =_xlfn.IFNA(VLOOKUP($C18&","&E3,$C$34:$D$112,2,FALSE),"-1") -> 5C | F18: =_xlfn.IFNA(VLOOKUP($C18&","&F3,$C$34:$D$112,2,FALSE),"-1") -> -1 | G18: =_xlfn.IFNA(VLOOKUP($C18&","&G3,$C$34:$D$112,2,FALSE),"-1") -> -1 | H18: =_xlfn.IFNA(VLOOKUP($C18&","&H3,$C$34:$D$112,2,FALSE),"-1") -> -1 | I18: =_xlfn.IFNA(VLOOKUP($C18&","&I3,$C$34:$D$112,2,FALSE),"-1") -> -1 | J18: =_xlfn.IFNA(VLOOKUP($C18&","&J3,$C$34:$D$112,2,FALSE),"-1") -> -1 | K18: =_xlfn.IFNA(VLOOKUP($C18&","&K3,$C$34:$D$112,2,FALSE),"-1") -> -1 | L18: =_xlfn.IFNA(VLOOKUP($C18&","&L3,$C$34:$D$112,2,FALSE),"-1") -> -1 | ... AB18: =_xlfn.IFNA(VLOOKUP($C18&","&AB3,$C$34:$D$112,2,FALSE),"-1") -> -1
A19: 2 | B19: =ROW()-4 -> 15 | C19: XCH | D19: =DEC2HEX(B19) -> F | E19: =_xlfn.IFNA(VLOOKUP($C19&","&E3,$C$34:$D$112,2,FALSE),"-1") -> 5D | F19: =_xlfn.IFNA(VLOOKUP($C19&","&F3,$C$34:$D$112,2,FALSE),"-1") -> -1 | G19: =_xlfn.IFNA(VLOOKUP($C19&","&G3,$C$34:$D$112,2,FALSE),"-1") -> -1 | H19: =_xlfn.IFNA(VLOOKUP($C19&","&H3,$C$34:$D$112,2,FALSE),"-1") -> -1 | I19: =_xlfn.IFNA(VLOOKUP($C19&","&I3,$C$34:$D$112,2,FALSE),"-1") -> -1 | J19: =_xlfn.IFNA(VLOOKUP($C19&","&J3,$C$34:$D$112,2,FALSE),"-1") -> -1 | K19: =_xlfn.IFNA(VLOOKUP($C19&","&K3,$C$34:$D$112,2,FALSE),"-1") -> -1 | L19: =_xlfn.IFNA(VLOOKUP($C19&","&L3,$C$34:$D$112,2,FALSE),"-1") -> -1 | ... AB19: =_xlfn.IFNA(VLOOKUP($C19&","&AB3,$C$34:$D$112,2,FALSE),"-1") -> -1
A20: 2 | B20: =ROW()-4 -> 16 | C20: XCHD | D20: =DEC2HEX(B20) -> 10 | E20: =_xlfn.IFNA(VLOOKUP($C20&","&E3,$C$34:$D$112,2,FALSE),"-1") -> 5E | F20: =_xlfn.IFNA(VLOOKUP($C20&","&F3,$C$34:$D$112,2,FALSE),"-1") -> -1 | G20: =_xlfn.IFNA(VLOOKUP($C20&","&G3,$C$34:$D$112,2,FALSE),"-1") -> -1 | H20: =_xlfn.IFNA(VLOOKUP($C20&","&H3,$C$34:$D$112,2,FALSE),"-1") -> -1 | I20: =_xlfn.IFNA(VLOOKUP($C20&","&I3,$C$34:$D$112,2,FALSE),"-1") -> -1 | J20: =_xlfn.IFNA(VLOOKUP($C20&","&J3,$C$34:$D$112,2,FALSE),"-1") -> -1 | K20: =_xlfn.IFNA(VLOOKUP($C20&","&K3,$C$34:$D$112,2,FALSE),"-1") -> -1 | L20: =_xlfn.IFNA(VLOOKUP($C20&","&L3,$C$34:$D$112,2,FALSE),"-1") -> -1 | ... AB20: =_xlfn.IFNA(VLOOKUP($C20&","&AB3,$C$34:$D$112,2,FALSE),"-1") -> -1
A21: 2 | B21: =ROW()-4 -> 17 | C21: XRL | D21: =DEC2HEX(B21) -> 11 | E21: =_xlfn.IFNA(VLOOKUP($C21&","&E3,$C$34:$D$112,2,FALSE),"-1") -> 5F | F21: =_xlfn.IFNA(VLOOKUP($C21&","&F3,$C$34:$D$112,2,FALSE),"-1") -> -1 | G21: =_xlfn.IFNA(VLOOKUP($C21&","&G3,$C$34:$D$112,2,FALSE),"-1") -> -1 | H21: =_xlfn.IFNA(VLOOKUP($C21&","&H3,$C$34:$D$112,2,FALSE),"-1") -> -1 | I21: =_xlfn.IFNA(VLOOKUP($C21&","&I3,$C$34:$D$112,2,FALSE),"-1") -> -1 | J21: =_xlfn.IFNA(VLOOKUP($C21&","&J3,$C$34:$D$112,2,FALSE),"-1") -> -1 | K21: =_xlfn.IFNA(VLOOKUP($C21&","&K3,$C$34:$D$112,2,FALSE),"-1") -> -1 | L21: =_xlfn.IFNA(VLOOKUP($C21&","&L3,$C$34:$D$112,2,FALSE),"-1") -> -1 | ... AB21: =_xlfn.IFNA(VLOOKUP($C21&","&AB3,$C$34:$D$112,2,FALSE),"-1") -> -1
A22: 3 | B22: =ROW()-4 -> 18 | C22: CJNE | D22: =DEC2HEX(B22) -> 12 | E22: =_xlfn.IFNA(VLOOKUP($C22&","&E3,$C$23:$D$112,2,FALSE),"-1") -> 15 | F22: =_xlfn.IFNA(VLOOKUP($C22&","&F3,$C$23:$D$112,2,FALSE),"-1") -> 16 | G22: =_xlfn.IFNA(VLOOKUP($C22&","&G3,$C$23:$D$112,2,FALSE),"-1") -> 17 | H22: =_xlfn.IFNA(VLOOKUP($C22&","&H3,$C$23:$D$112,2,FALSE),"-1") -> 18 | I22: =_xlfn.IFNA(VLOOKUP($C22&","&I3,$C$23:$D$112,2,FALSE),"-1") -> 19 | J22: =_xlfn.IFNA(VLOOKUP($C22&","&J3,$C$23:$D$112,2,FALSE),"-1") -> 1A | K22: =_xlfn.IFNA(VLOOKUP($C22&","&K3,$C$23:$D$112,2,FALSE),"-1") -> 1B | L22: =_xlfn.IFNA(VLOOKUP($C22&","&L3,$C$23:$D$112,2,FALSE),"-1") -> 1C | ... AB22: =_xlfn.IFNA(VLOOKUP($C22&","&AB3,$C$23:$D$112,2,FALSE),"-1") -> -1
